2024-05-27 20:26:18,020 INFO    StreamThr :67416 [internal.py:wandb_internal():86] W&B internal server running at pid: 67416, started at: 2024-05-27 20:26:18.020977
2024-05-27 20:26:18,021 DEBUG   HandlerThread:67416 [handler.py:handle_request():146] handle_request: status
2024-05-27 20:26:18,035 INFO    WriterThread:67416 [datastore.py:open_for_write():85] open: D:\Pycharm\ultralytics-main\wandb\run-20240527_202618-l9f2mmuw\run-l9f2mmuw.wandb
2024-05-27 20:26:18,036 DEBUG   SenderThread:67416 [sender.py:send():380] send: header
2024-05-27 20:26:18,038 DEBUG   SenderThread:67416 [sender.py:send():380] send: run
2024-05-27 20:26:18,916 INFO    SenderThread:67416 [dir_watcher.py:__init__():211] watching files in: D:\Pycharm\ultralytics-main\wandb\run-20240527_202618-l9f2mmuw\files
2024-05-27 20:26:18,916 INFO    SenderThread:67416 [sender.py:_start_run_threads():1124] run started: l9f2mmuw with start time 1716812778.02297
2024-05-27 20:26:18,920 DEBUG   HandlerThread:67416 [handler.py:handle_request():146] handle_request: check_version
2024-05-27 20:26:18,921 DEBUG   SenderThread:67416 [sender.py:send_request():407] send_request: check_version
2024-05-27 20:26:19,347 DEBUG   HandlerThread:67416 [handler.py:handle_request():146] handle_request: run_start
2024-05-27 20:26:19,515 DEBUG   HandlerThread:67416 [system_info.py:__init__():32] System info init
2024-05-27 20:26:19,515 DEBUG   HandlerThread:67416 [system_info.py:__init__():47] System info init done
2024-05-27 20:26:19,515 INFO    HandlerThread:67416 [system_monitor.py:start():194] Starting system monitor
2024-05-27 20:26:19,515 INFO    SystemMonitor:67416 [system_monitor.py:_start():158] Starting system asset monitoring threads
2024-05-27 20:26:19,515 INFO    HandlerThread:67416 [system_monitor.py:probe():214] Collecting system info
2024-05-27 20:26:19,524 INFO    SystemMonitor:67416 [interfaces.py:start():190] Started cpu monitoring
2024-05-27 20:26:19,525 INFO    SystemMonitor:67416 [interfaces.py:start():190] Started disk monitoring
2024-05-27 20:26:19,525 INFO    SystemMonitor:67416 [interfaces.py:start():190] Started gpu monitoring
2024-05-27 20:26:19,544 INFO    SystemMonitor:67416 [interfaces.py:start():190] Started memory monitoring
2024-05-27 20:26:19,570 INFO    SystemMonitor:67416 [interfaces.py:start():190] Started network monitoring
2024-05-27 20:26:19,579 DEBUG   HandlerThread:67416 [system_info.py:probe():196] Probing system
2024-05-27 20:26:19,580 DEBUG   HandlerThread:67416 [gitlib.py:_init_repo():56] git repository is invalid
2024-05-27 20:26:19,580 DEBUG   HandlerThread:67416 [system_info.py:probe():244] Probing system done
2024-05-27 20:26:19,580 DEBUG   HandlerThread:67416 [system_monitor.py:probe():223] {'os': 'Windows-10-10.0.22631-SP0', 'python': '3.9.18', 'heartbeatAt': '2024-05-27T12:26:19.579965', 'startedAt': '2024-05-27T12:26:18.003013', 'docker': None, 'cuda': None, 'args': (), 'state': 'running', 'program': 'D:\\Pycharm\\ultralytics-main\\train.py', 'codePathLocal': 'train.py', 'codePath': 'train.py', 'host': 'DESKTOP-VH2CUSJ', 'username': 'DELL', 'executable': 'D:\\Anaconda\\envs\\DL\\python.exe', 'cpu_count': 10, 'cpu_count_logical': 16, 'cpu_freq': {'current': 2400.0, 'min': 0.0, 'max': 2400.0}, 'cpu_freq_per_core': [{'current': 2400.0, 'min': 0.0, 'max': 2400.0}], 'disk': {'/': {'total': 244.13964462280273, 'used': 173.83461380004883}}, 'gpu': 'NVIDIA GeForce RTX 4050 Laptop GPU', 'gpu_count': 1, 'gpu_devices': [{'name': 'NVIDIA GeForce RTX 4050 Laptop GPU', 'memory_total': 6439305216}], 'memory': {'total': 15.692092895507812}}
2024-05-27 20:26:19,580 INFO    HandlerThread:67416 [system_monitor.py:probe():224] Finished collecting system info
2024-05-27 20:26:19,580 INFO    HandlerThread:67416 [system_monitor.py:probe():227] Publishing system info
2024-05-27 20:26:19,581 DEBUG   HandlerThread:67416 [system_info.py:_save_pip():52] Saving list of pip packages installed into the current environment
2024-05-27 20:26:19,581 DEBUG   HandlerThread:67416 [system_info.py:_save_pip():68] Saving pip packages done
2024-05-27 20:26:19,581 DEBUG   HandlerThread:67416 [system_info.py:_save_conda():75] Saving list of conda packages installed into the current environment
2024-05-27 20:26:19,920 INFO    Thread-16 :67416 [dir_watcher.py:_on_file_created():271] file/dir created: D:\Pycharm\ultralytics-main\wandb\run-20240527_202618-l9f2mmuw\files\requirements.txt
2024-05-27 20:26:19,920 INFO    Thread-16 :67416 [dir_watcher.py:_on_file_created():271] file/dir created: D:\Pycharm\ultralytics-main\wandb\run-20240527_202618-l9f2mmuw\files\conda-environment.yaml
2024-05-27 20:26:27,947 DEBUG   HandlerThread:67416 [system_info.py:_save_conda():87] Saving conda packages done
2024-05-27 20:26:27,947 INFO    HandlerThread:67416 [system_monitor.py:probe():229] Finished publishing system info
2024-05-27 20:26:28,001 INFO    Thread-16 :67416 [dir_watcher.py:_on_file_modified():288] file/dir modified: D:\Pycharm\ultralytics-main\wandb\run-20240527_202618-l9f2mmuw\files\conda-environment.yaml
2024-05-27 20:26:28,001 INFO    Thread-16 :67416 [dir_watcher.py:_on_file_created():271] file/dir created: D:\Pycharm\ultralytics-main\wandb\run-20240527_202618-l9f2mmuw\files\wandb-metadata.json
2024-05-27 20:26:28,067 DEBUG   HandlerThread:67416 [handler.py:handle_request():146] handle_request: status_report
2024-05-27 20:26:28,067 DEBUG   HandlerThread:67416 [handler.py:handle_request():146] handle_request: keepalive
2024-05-27 20:26:28,067 DEBUG   SenderThread:67416 [sender.py:send():380] send: files
2024-05-27 20:26:28,067 INFO    SenderThread:67416 [sender.py:_save_file():1380] saving file wandb-metadata.json with policy now
2024-05-27 20:26:28,074 DEBUG   HandlerThread:67416 [handler.py:handle_request():146] handle_request: stop_status
2024-05-27 20:26:28,075 DEBUG   SenderThread:67416 [sender.py:send_request():407] send_request: stop_status
2024-05-27 20:26:28,076 DEBUG   HandlerThread:67416 [handler.py:handle_request():146] handle_request: internal_messages
2024-05-27 20:26:28,305 DEBUG   SenderThread:67416 [sender.py:send():380] send: telemetry
2024-05-27 20:26:29,013 INFO    Thread-16 :67416 [dir_watcher.py:_on_file_created():271] file/dir created: D:\Pycharm\ultralytics-main\wandb\run-20240527_202618-l9f2mmuw\files\output.log
2024-05-27 20:26:29,099 ERROR   wandb-upload_0:67416 [internal_api.py:upload_file():2557] upload_file exception https://storage.googleapis.com/wandb-production.appspot.com/666233/runs/l9f2mmuw/wandb-metadata.json?Expires=1716899188&GoogleAccessId=gorilla-files-url-signer-man%40wandb-production.iam.gserviceaccount.com&Signature=QRG2bs16TjtK6mtudlO3EHRqdISb1yYlPXTffwilbQZkBbub8W%2BGtpvO7vCfpykQk3OnPmHkr4ohSVwZFGES5XRJqUdYhh4VpSvjR1pSkq%2FiRReY%2BNim5C9VVJvzXRjPBSyQMAdVNv0Ic0Q2jE2UBCIkuNlV8KgUrTOIQaFWI5fOBpC48ukAk6rlZJduGadv%2BH39xd%2BSBONmxA0AruEoUqFD5SIG95QPd1OccDw6yEdrK8zYqHm%2BpWAO%2B6Z1lk9cdlL2zpu%2BgoVRHt6d%2B8W5yDri%2B1F4eizkOo9%2Fc8g%2FGOf4NolfHf%2FVeBTDgZ1j36YabFNGZdu2tv5%2Blc4097oNqg%3D%3D: ('Connection aborted.', ConnectionResetError(10054, '远程主机强迫关闭了一个现有的连接。', None, 10054, None))
2024-05-27 20:26:29,103 ERROR   wandb-upload_0:67416 [internal_api.py:upload_file():2559] upload_file request headers: {'User-Agent': 'python-requests/2.28.2', 'Accept-Encoding': 'gzip, deflate', 'Accept': '*/*', 'Connection': 'keep-alive', 'Content-Length': '1195'}
2024-05-27 20:26:29,103 ERROR   wandb-upload_0:67416 [internal_api.py:upload_file():2561] upload_file response body: 
2024-05-27 20:26:29,321 DEBUG   HandlerThread:67416 [handler.py:handle_request():146] handle_request: status_report
2024-05-27 20:26:30,418 ERROR   wandb-upload_0:67416 [internal_api.py:upload_file():2557] upload_file exception https://storage.googleapis.com/wandb-production.appspot.com/666233/runs/l9f2mmuw/wandb-metadata.json?Expires=1716899188&GoogleAccessId=gorilla-files-url-signer-man%40wandb-production.iam.gserviceaccount.com&Signature=QRG2bs16TjtK6mtudlO3EHRqdISb1yYlPXTffwilbQZkBbub8W%2BGtpvO7vCfpykQk3OnPmHkr4ohSVwZFGES5XRJqUdYhh4VpSvjR1pSkq%2FiRReY%2BNim5C9VVJvzXRjPBSyQMAdVNv0Ic0Q2jE2UBCIkuNlV8KgUrTOIQaFWI5fOBpC48ukAk6rlZJduGadv%2BH39xd%2BSBONmxA0AruEoUqFD5SIG95QPd1OccDw6yEdrK8zYqHm%2BpWAO%2B6Z1lk9cdlL2zpu%2BgoVRHt6d%2B8W5yDri%2B1F4eizkOo9%2Fc8g%2FGOf4NolfHf%2FVeBTDgZ1j36YabFNGZdu2tv5%2Blc4097oNqg%3D%3D: ('Connection aborted.', ConnectionResetError(10054, '远程主机强迫关闭了一个现有的连接。', None, 10054, None))
2024-05-27 20:26:30,418 ERROR   wandb-upload_0:67416 [internal_api.py:upload_file():2559] upload_file request headers: {'User-Agent': 'python-requests/2.28.2', 'Accept-Encoding': 'gzip, deflate', 'Accept': '*/*', 'Connection': 'keep-alive', 'Content-Length': '1195'}
2024-05-27 20:26:30,418 ERROR   wandb-upload_0:67416 [internal_api.py:upload_file():2561] upload_file response body: 
2024-05-27 20:26:31,035 INFO    Thread-16 :67416 [dir_watcher.py:_on_file_modified():288] file/dir modified: D:\Pycharm\ultralytics-main\wandb\run-20240527_202618-l9f2mmuw\files\output.log
2024-05-27 20:26:32,868 ERROR   wandb-upload_0:67416 [internal_api.py:upload_file():2557] upload_file exception https://storage.googleapis.com/wandb-production.appspot.com/666233/runs/l9f2mmuw/wandb-metadata.json?Expires=1716899188&GoogleAccessId=gorilla-files-url-signer-man%40wandb-production.iam.gserviceaccount.com&Signature=QRG2bs16TjtK6mtudlO3EHRqdISb1yYlPXTffwilbQZkBbub8W%2BGtpvO7vCfpykQk3OnPmHkr4ohSVwZFGES5XRJqUdYhh4VpSvjR1pSkq%2FiRReY%2BNim5C9VVJvzXRjPBSyQMAdVNv0Ic0Q2jE2UBCIkuNlV8KgUrTOIQaFWI5fOBpC48ukAk6rlZJduGadv%2BH39xd%2BSBONmxA0AruEoUqFD5SIG95QPd1OccDw6yEdrK8zYqHm%2BpWAO%2B6Z1lk9cdlL2zpu%2BgoVRHt6d%2B8W5yDri%2B1F4eizkOo9%2Fc8g%2FGOf4NolfHf%2FVeBTDgZ1j36YabFNGZdu2tv5%2Blc4097oNqg%3D%3D: ('Connection aborted.', ConnectionResetError(10054, '远程主机强迫关闭了一个现有的连接。', None, 10054, None))
2024-05-27 20:26:32,868 ERROR   wandb-upload_0:67416 [internal_api.py:upload_file():2559] upload_file request headers: {'User-Agent': 'python-requests/2.28.2', 'Accept-Encoding': 'gzip, deflate', 'Accept': '*/*', 'Connection': 'keep-alive', 'Content-Length': '1195'}
2024-05-27 20:26:32,868 ERROR   wandb-upload_0:67416 [internal_api.py:upload_file():2561] upload_file response body: 
2024-05-27 20:26:32,868 INFO    wandb-upload_0:67416 [retry.py:__call__():172] Retry attempt failed:
Traceback (most recent call last):
  File "D:\Anaconda\envs\DL\lib\site-packages\urllib3\connectionpool.py", line 715, in urlopen
    httplib_response = self._make_request(
  File "D:\Anaconda\envs\DL\lib\site-packages\urllib3\connectionpool.py", line 404, in _make_request
    self._validate_conn(conn)
  File "D:\Anaconda\envs\DL\lib\site-packages\urllib3\connectionpool.py", line 1058, in _validate_conn
    conn.connect()
  File "D:\Anaconda\envs\DL\lib\site-packages\urllib3\connection.py", line 419, in connect
    self.sock = ssl_wrap_socket(
  File "D:\Anaconda\envs\DL\lib\site-packages\urllib3\util\ssl_.py", line 449, in ssl_wrap_socket
    ssl_sock = _ssl_wrap_socket_impl(
  File "D:\Anaconda\envs\DL\lib\site-packages\urllib3\util\ssl_.py", line 493, in _ssl_wrap_socket_impl
    return ssl_context.wrap_socket(sock, server_hostname=server_hostname)
  File "D:\Anaconda\envs\DL\lib\ssl.py", line 501, in wrap_socket
    return self.sslsocket_class._create(
  File "D:\Anaconda\envs\DL\lib\ssl.py", line 1074, in _create
    self.do_handshake()
  File "D:\Anaconda\envs\DL\lib\ssl.py", line 1343, in do_handshake
    self._sslobj.do_handshake()
ConnectionResetError: [WinError 10054] 远程主机强迫关闭了一个现有的连接。

During handling of the above exception, another exception occurred:

Traceback (most recent call last):
  File "D:\Anaconda\envs\DL\lib\site-packages\requests\adapters.py", line 489, in send
    resp = conn.urlopen(
  File "D:\Anaconda\envs\DL\lib\site-packages\urllib3\connectionpool.py", line 799, in urlopen
    retries = retries.increment(
  File "D:\Anaconda\envs\DL\lib\site-packages\urllib3\util\retry.py", line 550, in increment
    raise six.reraise(type(error), error, _stacktrace)
  File "D:\Anaconda\envs\DL\lib\site-packages\urllib3\packages\six.py", line 769, in reraise
    raise value.with_traceback(tb)
  File "D:\Anaconda\envs\DL\lib\site-packages\urllib3\connectionpool.py", line 715, in urlopen
    httplib_response = self._make_request(
  File "D:\Anaconda\envs\DL\lib\site-packages\urllib3\connectionpool.py", line 404, in _make_request
    self._validate_conn(conn)
  File "D:\Anaconda\envs\DL\lib\site-packages\urllib3\connectionpool.py", line 1058, in _validate_conn
    conn.connect()
  File "D:\Anaconda\envs\DL\lib\site-packages\urllib3\connection.py", line 419, in connect
    self.sock = ssl_wrap_socket(
  File "D:\Anaconda\envs\DL\lib\site-packages\urllib3\util\ssl_.py", line 449, in ssl_wrap_socket
    ssl_sock = _ssl_wrap_socket_impl(
  File "D:\Anaconda\envs\DL\lib\site-packages\urllib3\util\ssl_.py", line 493, in _ssl_wrap_socket_impl
    return ssl_context.wrap_socket(sock, server_hostname=server_hostname)
  File "D:\Anaconda\envs\DL\lib\ssl.py", line 501, in wrap_socket
    return self.sslsocket_class._create(
  File "D:\Anaconda\envs\DL\lib\ssl.py", line 1074, in _create
    self.do_handshake()
  File "D:\Anaconda\envs\DL\lib\ssl.py", line 1343, in do_handshake
    self._sslobj.do_handshake()
urllib3.exceptions.ProtocolError: ('Connection aborted.', ConnectionResetError(10054, '远程主机强迫关闭了一个现有的连接。', None, 10054, None))

During handling of the above exception, another exception occurred:

Traceback (most recent call last):
  File "D:\Anaconda\envs\DL\lib\site-packages\wandb\sdk\internal\internal_api.py", line 2550, in upload_file
    response = self._upload_file_session.put(
  File "D:\Anaconda\envs\DL\lib\site-packages\requests\sessions.py", line 647, in put
    return self.request("PUT", url, data=data, **kwargs)
  File "D:\Anaconda\envs\DL\lib\site-packages\requests\sessions.py", line 587, in request
    resp = self.send(prep, **send_kwargs)
  File "D:\Anaconda\envs\DL\lib\site-packages\requests\sessions.py", line 701, in send
    r = adapter.send(request, **kwargs)
  File "D:\Anaconda\envs\DL\lib\site-packages\requests\adapters.py", line 547, in send
    raise ConnectionError(err, request=request)
requests.exceptions.ConnectionError: ('Connection aborted.', ConnectionResetError(10054, '远程主机强迫关闭了一个现有的连接。', None, 10054, None))

During handling of the above exception, another exception occurred:

Traceback (most recent call last):
  File "D:\Anaconda\envs\DL\lib\site-packages\wandb\sdk\lib\retry.py", line 131, in __call__
    result = self._call_fn(*args, **kwargs)
  File "D:\Anaconda\envs\DL\lib\site-packages\wandb\sdk\internal\internal_api.py", line 2581, in upload_file
    raise _e.with_traceback(sys.exc_info()[2])
  File "D:\Anaconda\envs\DL\lib\site-packages\wandb\sdk\internal\internal_api.py", line 2550, in upload_file
    response = self._upload_file_session.put(
  File "D:\Anaconda\envs\DL\lib\site-packages\requests\sessions.py", line 647, in put
    return self.request("PUT", url, data=data, **kwargs)
  File "D:\Anaconda\envs\DL\lib\site-packages\requests\sessions.py", line 587, in request
    resp = self.send(prep, **send_kwargs)
  File "D:\Anaconda\envs\DL\lib\site-packages\requests\sessions.py", line 701, in send
    r = adapter.send(request, **kwargs)
  File "D:\Anaconda\envs\DL\lib\site-packages\requests\adapters.py", line 547, in send
    raise ConnectionError(err, request=request)
wandb.sdk.lib.retry.TransientError: None
2024-05-27 20:26:34,378 DEBUG   HandlerThread:67416 [handler.py:handle_request():146] handle_request: status_report
2024-05-27 20:26:37,920 ERROR   wandb-upload_0:67416 [internal_api.py:upload_file():2557] upload_file exception https://storage.googleapis.com/wandb-production.appspot.com/666233/runs/l9f2mmuw/wandb-metadata.json?Expires=1716899188&GoogleAccessId=gorilla-files-url-signer-man%40wandb-production.iam.gserviceaccount.com&Signature=QRG2bs16TjtK6mtudlO3EHRqdISb1yYlPXTffwilbQZkBbub8W%2BGtpvO7vCfpykQk3OnPmHkr4ohSVwZFGES5XRJqUdYhh4VpSvjR1pSkq%2FiRReY%2BNim5C9VVJvzXRjPBSyQMAdVNv0Ic0Q2jE2UBCIkuNlV8KgUrTOIQaFWI5fOBpC48ukAk6rlZJduGadv%2BH39xd%2BSBONmxA0AruEoUqFD5SIG95QPd1OccDw6yEdrK8zYqHm%2BpWAO%2B6Z1lk9cdlL2zpu%2BgoVRHt6d%2B8W5yDri%2B1F4eizkOo9%2Fc8g%2FGOf4NolfHf%2FVeBTDgZ1j36YabFNGZdu2tv5%2Blc4097oNqg%3D%3D: ('Connection aborted.', ConnectionResetError(10054, '远程主机强迫关闭了一个现有的连接。', None, 10054, None))
2024-05-27 20:26:37,920 ERROR   wandb-upload_0:67416 [internal_api.py:upload_file():2559] upload_file request headers: {'User-Agent': 'python-requests/2.28.2', 'Accept-Encoding': 'gzip, deflate', 'Accept': '*/*', 'Connection': 'keep-alive', 'Content-Length': '1195'}
2024-05-27 20:26:37,920 ERROR   wandb-upload_0:67416 [internal_api.py:upload_file():2561] upload_file response body: 
2024-05-27 20:26:39,418 DEBUG   HandlerThread:67416 [handler.py:handle_request():146] handle_request: status_report
2024-05-27 20:26:43,078 DEBUG   HandlerThread:67416 [handler.py:handle_request():146] handle_request: internal_messages
2024-05-27 20:26:43,087 DEBUG   HandlerThread:67416 [handler.py:handle_request():146] handle_request: stop_status
2024-05-27 20:26:43,087 DEBUG   SenderThread:67416 [sender.py:send_request():407] send_request: stop_status
2024-05-27 20:26:45,198 DEBUG   HandlerThread:67416 [handler.py:handle_request():146] handle_request: status_report
2024-05-27 20:26:47,180 INFO    Thread-16 :67416 [dir_watcher.py:_on_file_modified():288] file/dir modified: D:\Pycharm\ultralytics-main\wandb\run-20240527_202618-l9f2mmuw\files\output.log
2024-05-27 20:26:48,040 ERROR   wandb-upload_0:67416 [internal_api.py:upload_file():2557] upload_file exception https://storage.googleapis.com/wandb-production.appspot.com/666233/runs/l9f2mmuw/wandb-metadata.json?Expires=1716899188&GoogleAccessId=gorilla-files-url-signer-man%40wandb-production.iam.gserviceaccount.com&Signature=QRG2bs16TjtK6mtudlO3EHRqdISb1yYlPXTffwilbQZkBbub8W%2BGtpvO7vCfpykQk3OnPmHkr4ohSVwZFGES5XRJqUdYhh4VpSvjR1pSkq%2FiRReY%2BNim5C9VVJvzXRjPBSyQMAdVNv0Ic0Q2jE2UBCIkuNlV8KgUrTOIQaFWI5fOBpC48ukAk6rlZJduGadv%2BH39xd%2BSBONmxA0AruEoUqFD5SIG95QPd1OccDw6yEdrK8zYqHm%2BpWAO%2B6Z1lk9cdlL2zpu%2BgoVRHt6d%2B8W5yDri%2B1F4eizkOo9%2Fc8g%2FGOf4NolfHf%2FVeBTDgZ1j36YabFNGZdu2tv5%2Blc4097oNqg%3D%3D: ('Connection aborted.', ConnectionResetError(10054, '远程主机强迫关闭了一个现有的连接。', None, 10054, None))
2024-05-27 20:26:48,040 ERROR   wandb-upload_0:67416 [internal_api.py:upload_file():2559] upload_file request headers: {'User-Agent': 'python-requests/2.28.2', 'Accept-Encoding': 'gzip, deflate', 'Accept': '*/*', 'Connection': 'keep-alive', 'Content-Length': '1195'}
2024-05-27 20:26:48,040 ERROR   wandb-upload_0:67416 [internal_api.py:upload_file():2561] upload_file response body: 
2024-05-27 20:26:48,191 INFO    Thread-16 :67416 [dir_watcher.py:_on_file_modified():288] file/dir modified: D:\Pycharm\ultralytics-main\wandb\run-20240527_202618-l9f2mmuw\files\output.log
2024-05-27 20:26:49,206 INFO    Thread-16 :67416 [dir_watcher.py:_on_file_modified():288] file/dir modified: D:\Pycharm\ultralytics-main\wandb\run-20240527_202618-l9f2mmuw\files\output.log
2024-05-27 20:26:50,706 DEBUG   HandlerThread:67416 [handler.py:handle_request():146] handle_request: status_report
2024-05-27 20:26:51,231 INFO    Thread-16 :67416 [dir_watcher.py:_on_file_modified():288] file/dir modified: D:\Pycharm\ultralytics-main\wandb\run-20240527_202618-l9f2mmuw\files\output.log
2024-05-27 20:26:51,232 INFO    Thread-16 :67416 [dir_watcher.py:_on_file_modified():288] file/dir modified: D:\Pycharm\ultralytics-main\wandb\run-20240527_202618-l9f2mmuw\files\config.yaml
2024-05-27 20:26:55,264 INFO    Thread-16 :67416 [dir_watcher.py:_on_file_modified():288] file/dir modified: D:\Pycharm\ultralytics-main\wandb\run-20240527_202618-l9f2mmuw\files\output.log
2024-05-27 20:26:56,121 DEBUG   HandlerThread:67416 [handler.py:handle_request():146] handle_request: status_report
2024-05-27 20:26:56,277 INFO    Thread-16 :67416 [dir_watcher.py:_on_file_modified():288] file/dir modified: D:\Pycharm\ultralytics-main\wandb\run-20240527_202618-l9f2mmuw\files\output.log
2024-05-27 20:26:58,070 DEBUG   HandlerThread:67416 [handler.py:handle_request():146] handle_request: internal_messages
2024-05-27 20:26:58,117 DEBUG   HandlerThread:67416 [handler.py:handle_request():146] handle_request: stop_status
2024-05-27 20:26:58,118 DEBUG   SenderThread:67416 [sender.py:send_request():407] send_request: stop_status
2024-05-27 20:26:58,286 INFO    Thread-16 :67416 [dir_watcher.py:_on_file_modified():288] file/dir modified: D:\Pycharm\ultralytics-main\wandb\run-20240527_202618-l9f2mmuw\files\output.log
2024-05-27 20:27:00,291 INFO    Thread-16 :67416 [dir_watcher.py:_on_file_modified():288] file/dir modified: D:\Pycharm\ultralytics-main\wandb\run-20240527_202618-l9f2mmuw\files\output.log
2024-05-27 20:27:01,297 DEBUG   HandlerThread:67416 [handler.py:handle_request():146] handle_request: status_report
2024-05-27 20:27:02,308 INFO    Thread-16 :67416 [dir_watcher.py:_on_file_modified():288] file/dir modified: D:\Pycharm\ultralytics-main\wandb\run-20240527_202618-l9f2mmuw\files\output.log
2024-05-27 20:27:04,323 INFO    Thread-16 :67416 [dir_watcher.py:_on_file_modified():288] file/dir modified: D:\Pycharm\ultralytics-main\wandb\run-20240527_202618-l9f2mmuw\files\output.log
