2024-05-17 10:57:26,926 INFO    StreamThr :11840 [internal.py:wandb_internal():86] W&B internal server running at pid: 11840, started at: 2024-05-17 10:57:26.926042
2024-05-17 10:57:26,941 DEBUG   HandlerThread:11840 [handler.py:handle_request():146] handle_request: status
2024-05-17 10:57:26,941 INFO    WriterThread:11840 [datastore.py:open_for_write():85] open: D:\Pycharm\ultralytics-main\wandb\run-20240517_105726-8s4xcs7t\run-8s4xcs7t.wandb
2024-05-17 10:57:26,941 DEBUG   SenderThread:11840 [sender.py:send():380] send: header
2024-05-17 10:57:26,941 DEBUG   SenderThread:11840 [sender.py:send():380] send: run
2024-05-17 10:57:27,724 INFO    SenderThread:11840 [dir_watcher.py:__init__():211] watching files in: D:\Pycharm\ultralytics-main\wandb\run-20240517_105726-8s4xcs7t\files
2024-05-17 10:57:27,724 INFO    SenderThread:11840 [sender.py:_start_run_threads():1124] run started: 8s4xcs7t with start time 1715914646.926041
2024-05-17 10:57:27,724 DEBUG   HandlerThread:11840 [handler.py:handle_request():146] handle_request: check_version
2024-05-17 10:57:27,724 DEBUG   SenderThread:11840 [sender.py:send_request():407] send_request: check_version
2024-05-17 10:57:28,116 DEBUG   HandlerThread:11840 [handler.py:handle_request():146] handle_request: run_start
2024-05-17 10:57:28,147 DEBUG   HandlerThread:11840 [system_info.py:__init__():32] System info init
2024-05-17 10:57:28,147 DEBUG   HandlerThread:11840 [system_info.py:__init__():47] System info init done
2024-05-17 10:57:28,147 INFO    HandlerThread:11840 [system_monitor.py:start():194] Starting system monitor
2024-05-17 10:57:28,147 INFO    SystemMonitor:11840 [system_monitor.py:_start():158] Starting system asset monitoring threads
2024-05-17 10:57:28,147 INFO    HandlerThread:11840 [system_monitor.py:probe():214] Collecting system info
2024-05-17 10:57:28,147 INFO    SystemMonitor:11840 [interfaces.py:start():190] Started cpu monitoring
2024-05-17 10:57:28,147 INFO    SystemMonitor:11840 [interfaces.py:start():190] Started disk monitoring
2024-05-17 10:57:28,147 INFO    SystemMonitor:11840 [interfaces.py:start():190] Started gpu monitoring
2024-05-17 10:57:28,147 INFO    SystemMonitor:11840 [interfaces.py:start():190] Started memory monitoring
2024-05-17 10:57:28,163 INFO    SystemMonitor:11840 [interfaces.py:start():190] Started network monitoring
2024-05-17 10:57:28,163 DEBUG   HandlerThread:11840 [system_info.py:probe():196] Probing system
2024-05-17 10:57:28,163 DEBUG   HandlerThread:11840 [gitlib.py:_init_repo():56] git repository is invalid
2024-05-17 10:57:28,163 DEBUG   HandlerThread:11840 [system_info.py:probe():244] Probing system done
2024-05-17 10:57:28,163 DEBUG   HandlerThread:11840 [system_monitor.py:probe():223] {'os': 'Windows-10-10.0.22631-SP0', 'python': '3.9.18', 'heartbeatAt': '2024-05-17T02:57:28.163567', 'startedAt': '2024-05-17T02:57:26.904914', 'docker': None, 'cuda': None, 'args': (), 'state': 'running', 'program': 'D:\\Pycharm\\ultralytics-main\\train.py', 'codePathLocal': 'train.py', 'codePath': 'train.py', 'host': 'DESKTOP-VH2CUSJ', 'username': 'DELL', 'executable': 'D:\\Anaconda\\envs\\DL\\python.exe', 'cpu_count': 10, 'cpu_count_logical': 16, 'cpu_freq': {'current': 2400.0, 'min': 0.0, 'max': 2400.0}, 'cpu_freq_per_core': [{'current': 2400.0, 'min': 0.0, 'max': 2400.0}], 'disk': {'/': {'total': 244.13964462280273, 'used': 177.18484115600586}}, 'gpu': 'NVIDIA GeForce RTX 4050 Laptop GPU', 'gpu_count': 1, 'gpu_devices': [{'name': 'NVIDIA GeForce RTX 4050 Laptop GPU', 'memory_total': 6439305216}], 'memory': {'total': 15.692092895507812}}
2024-05-17 10:57:28,163 INFO    HandlerThread:11840 [system_monitor.py:probe():224] Finished collecting system info
2024-05-17 10:57:28,163 INFO    HandlerThread:11840 [system_monitor.py:probe():227] Publishing system info
2024-05-17 10:57:28,163 DEBUG   HandlerThread:11840 [system_info.py:_save_pip():52] Saving list of pip packages installed into the current environment
2024-05-17 10:57:28,163 DEBUG   HandlerThread:11840 [system_info.py:_save_pip():68] Saving pip packages done
2024-05-17 10:57:28,163 DEBUG   HandlerThread:11840 [system_info.py:_save_conda():75] Saving list of conda packages installed into the current environment
2024-05-17 10:57:28,728 INFO    Thread-16 :11840 [dir_watcher.py:_on_file_created():271] file/dir created: D:\Pycharm\ultralytics-main\wandb\run-20240517_105726-8s4xcs7t\files\conda-environment.yaml
2024-05-17 10:57:28,728 INFO    Thread-16 :11840 [dir_watcher.py:_on_file_created():271] file/dir created: D:\Pycharm\ultralytics-main\wandb\run-20240517_105726-8s4xcs7t\files\requirements.txt
2024-05-17 10:57:37,666 DEBUG   HandlerThread:11840 [system_info.py:_save_conda():87] Saving conda packages done
2024-05-17 10:57:37,682 INFO    HandlerThread:11840 [system_monitor.py:probe():229] Finished publishing system info
2024-05-17 10:57:37,697 DEBUG   HandlerThread:11840 [handler.py:handle_request():146] handle_request: status_report
2024-05-17 10:57:37,697 DEBUG   HandlerThread:11840 [handler.py:handle_request():146] handle_request: keepalive
2024-05-17 10:57:37,697 DEBUG   HandlerThread:11840 [handler.py:handle_request():146] handle_request: status_report
2024-05-17 10:57:37,697 DEBUG   SenderThread:11840 [sender.py:send():380] send: files
2024-05-17 10:57:37,697 INFO    SenderThread:11840 [sender.py:_save_file():1380] saving file wandb-metadata.json with policy now
2024-05-17 10:57:37,713 DEBUG   HandlerThread:11840 [handler.py:handle_request():146] handle_request: stop_status
2024-05-17 10:57:37,713 DEBUG   SenderThread:11840 [sender.py:send_request():407] send_request: stop_status
2024-05-17 10:57:37,713 DEBUG   HandlerThread:11840 [handler.py:handle_request():146] handle_request: internal_messages
2024-05-17 10:57:37,760 INFO    Thread-16 :11840 [dir_watcher.py:_on_file_modified():288] file/dir modified: D:\Pycharm\ultralytics-main\wandb\run-20240517_105726-8s4xcs7t\files\conda-environment.yaml
2024-05-17 10:57:37,760 INFO    Thread-16 :11840 [dir_watcher.py:_on_file_created():271] file/dir created: D:\Pycharm\ultralytics-main\wandb\run-20240517_105726-8s4xcs7t\files\wandb-metadata.json
2024-05-17 10:57:38,340 DEBUG   SenderThread:11840 [sender.py:send():380] send: telemetry
2024-05-17 10:57:38,544 ERROR   wandb-upload_0:11840 [internal_api.py:upload_file():2557] upload_file exception https://storage.googleapis.com/wandb-production.appspot.com/666233/runs/8s4xcs7t/wandb-metadata.json?Expires=1716001058&GoogleAccessId=gorilla-files-url-signer-man%40wandb-production.iam.gserviceaccount.com&Signature=ec329%2F0V3AAJRPiDl8T24eTHx%2F5eCf60h8pu0Zwhuhd1J9hoBYdundXmyO%2F9m4ij7eRPNJtcX2VI6fIiPHFTv6Ce2eb3pl9sVirFOqBFrq7Z3A%2FiT7ial%2B7uge0qIYnw3l%2Bl7GRP5XvPByp6jAEXKRayQWxzHK0BtR8Puj%2B2OsvbnUmKQDEv%2BrzrcKqZsC6Ao%2F5huX7AQ2wUDcFaYay4iRSk7%2FTj%2Fm9bH1cMVi%2BHhZARbdv8JI7DCDNGEjOohVTleqIgtbueSUmFQjsYD%2FWHNxTvlKoqxNM3hlkfocG29U%2B2s%2FhkCaSMGcqmK92LL83TEJpwwaN2xY4Nag9ql%2F6EgA%3D%3D: ('Connection aborted.', ConnectionResetError(10054, '远程主机强迫关闭了一个现有的连接。', None, 10054, None))
2024-05-17 10:57:38,544 ERROR   wandb-upload_0:11840 [internal_api.py:upload_file():2559] upload_file request headers: {'User-Agent': 'python-requests/2.28.2', 'Accept-Encoding': 'gzip, deflate', 'Accept': '*/*', 'Connection': 'keep-alive', 'Content-Length': '1195'}
2024-05-17 10:57:38,544 ERROR   wandb-upload_0:11840 [internal_api.py:upload_file():2561] upload_file response body: 
2024-05-17 10:57:38,764 INFO    Thread-16 :11840 [dir_watcher.py:_on_file_created():271] file/dir created: D:\Pycharm\ultralytics-main\wandb\run-20240517_105726-8s4xcs7t\files\output.log
2024-05-17 10:57:40,129 ERROR   wandb-upload_0:11840 [internal_api.py:upload_file():2557] upload_file exception https://storage.googleapis.com/wandb-production.appspot.com/666233/runs/8s4xcs7t/wandb-metadata.json?Expires=1716001058&GoogleAccessId=gorilla-files-url-signer-man%40wandb-production.iam.gserviceaccount.com&Signature=ec329%2F0V3AAJRPiDl8T24eTHx%2F5eCf60h8pu0Zwhuhd1J9hoBYdundXmyO%2F9m4ij7eRPNJtcX2VI6fIiPHFTv6Ce2eb3pl9sVirFOqBFrq7Z3A%2FiT7ial%2B7uge0qIYnw3l%2Bl7GRP5XvPByp6jAEXKRayQWxzHK0BtR8Puj%2B2OsvbnUmKQDEv%2BrzrcKqZsC6Ao%2F5huX7AQ2wUDcFaYay4iRSk7%2FTj%2Fm9bH1cMVi%2BHhZARbdv8JI7DCDNGEjOohVTleqIgtbueSUmFQjsYD%2FWHNxTvlKoqxNM3hlkfocG29U%2B2s%2FhkCaSMGcqmK92LL83TEJpwwaN2xY4Nag9ql%2F6EgA%3D%3D: ('Connection aborted.', ConnectionResetError(10054, '远程主机强迫关闭了一个现有的连接。', None, 10054, None))
2024-05-17 10:57:40,129 ERROR   wandb-upload_0:11840 [internal_api.py:upload_file():2559] upload_file request headers: {'User-Agent': 'python-requests/2.28.2', 'Accept-Encoding': 'gzip, deflate', 'Accept': '*/*', 'Connection': 'keep-alive', 'Content-Length': '1195'}
2024-05-17 10:57:40,129 ERROR   wandb-upload_0:11840 [internal_api.py:upload_file():2561] upload_file response body: 
2024-05-17 10:57:40,770 INFO    Thread-16 :11840 [dir_watcher.py:_on_file_modified():288] file/dir modified: D:\Pycharm\ultralytics-main\wandb\run-20240517_105726-8s4xcs7t\files\output.log
2024-05-17 10:57:42,370 DEBUG   HandlerThread:11840 [handler.py:handle_request():146] handle_request: status_report
2024-05-17 10:57:42,950 ERROR   wandb-upload_0:11840 [internal_api.py:upload_file():2557] upload_file exception https://storage.googleapis.com/wandb-production.appspot.com/666233/runs/8s4xcs7t/wandb-metadata.json?Expires=1716001058&GoogleAccessId=gorilla-files-url-signer-man%40wandb-production.iam.gserviceaccount.com&Signature=ec329%2F0V3AAJRPiDl8T24eTHx%2F5eCf60h8pu0Zwhuhd1J9hoBYdundXmyO%2F9m4ij7eRPNJtcX2VI6fIiPHFTv6Ce2eb3pl9sVirFOqBFrq7Z3A%2FiT7ial%2B7uge0qIYnw3l%2Bl7GRP5XvPByp6jAEXKRayQWxzHK0BtR8Puj%2B2OsvbnUmKQDEv%2BrzrcKqZsC6Ao%2F5huX7AQ2wUDcFaYay4iRSk7%2FTj%2Fm9bH1cMVi%2BHhZARbdv8JI7DCDNGEjOohVTleqIgtbueSUmFQjsYD%2FWHNxTvlKoqxNM3hlkfocG29U%2B2s%2FhkCaSMGcqmK92LL83TEJpwwaN2xY4Nag9ql%2F6EgA%3D%3D: ('Connection aborted.', ConnectionResetError(10054, '远程主机强迫关闭了一个现有的连接。', None, 10054, None))
2024-05-17 10:57:42,950 ERROR   wandb-upload_0:11840 [internal_api.py:upload_file():2559] upload_file request headers: {'User-Agent': 'python-requests/2.28.2', 'Accept-Encoding': 'gzip, deflate', 'Accept': '*/*', 'Connection': 'keep-alive', 'Content-Length': '1195'}
2024-05-17 10:57:42,950 ERROR   wandb-upload_0:11840 [internal_api.py:upload_file():2561] upload_file response body: 
2024-05-17 10:57:42,950 INFO    wandb-upload_0:11840 [retry.py:__call__():172] Retry attempt failed:
Traceback (most recent call last):
  File "D:\Anaconda\envs\DL\lib\site-packages\urllib3\connectionpool.py", line 715, in urlopen
    httplib_response = self._make_request(
  File "D:\Anaconda\envs\DL\lib\site-packages\urllib3\connectionpool.py", line 404, in _make_request
    self._validate_conn(conn)
  File "D:\Anaconda\envs\DL\lib\site-packages\urllib3\connectionpool.py", line 1058, in _validate_conn
    conn.connect()
  File "D:\Anaconda\envs\DL\lib\site-packages\urllib3\connection.py", line 419, in connect
    self.sock = ssl_wrap_socket(
  File "D:\Anaconda\envs\DL\lib\site-packages\urllib3\util\ssl_.py", line 449, in ssl_wrap_socket
    ssl_sock = _ssl_wrap_socket_impl(
  File "D:\Anaconda\envs\DL\lib\site-packages\urllib3\util\ssl_.py", line 493, in _ssl_wrap_socket_impl
    return ssl_context.wrap_socket(sock, server_hostname=server_hostname)
  File "D:\Anaconda\envs\DL\lib\ssl.py", line 501, in wrap_socket
    return self.sslsocket_class._create(
  File "D:\Anaconda\envs\DL\lib\ssl.py", line 1074, in _create
    self.do_handshake()
  File "D:\Anaconda\envs\DL\lib\ssl.py", line 1343, in do_handshake
    self._sslobj.do_handshake()
ConnectionResetError: [WinError 10054] 远程主机强迫关闭了一个现有的连接。

During handling of the above exception, another exception occurred:

Traceback (most recent call last):
  File "D:\Anaconda\envs\DL\lib\site-packages\requests\adapters.py", line 489, in send
    resp = conn.urlopen(
  File "D:\Anaconda\envs\DL\lib\site-packages\urllib3\connectionpool.py", line 799, in urlopen
    retries = retries.increment(
  File "D:\Anaconda\envs\DL\lib\site-packages\urllib3\util\retry.py", line 550, in increment
    raise six.reraise(type(error), error, _stacktrace)
  File "D:\Anaconda\envs\DL\lib\site-packages\urllib3\packages\six.py", line 769, in reraise
    raise value.with_traceback(tb)
  File "D:\Anaconda\envs\DL\lib\site-packages\urllib3\connectionpool.py", line 715, in urlopen
    httplib_response = self._make_request(
  File "D:\Anaconda\envs\DL\lib\site-packages\urllib3\connectionpool.py", line 404, in _make_request
    self._validate_conn(conn)
  File "D:\Anaconda\envs\DL\lib\site-packages\urllib3\connectionpool.py", line 1058, in _validate_conn
    conn.connect()
  File "D:\Anaconda\envs\DL\lib\site-packages\urllib3\connection.py", line 419, in connect
    self.sock = ssl_wrap_socket(
  File "D:\Anaconda\envs\DL\lib\site-packages\urllib3\util\ssl_.py", line 449, in ssl_wrap_socket
    ssl_sock = _ssl_wrap_socket_impl(
  File "D:\Anaconda\envs\DL\lib\site-packages\urllib3\util\ssl_.py", line 493, in _ssl_wrap_socket_impl
    return ssl_context.wrap_socket(sock, server_hostname=server_hostname)
  File "D:\Anaconda\envs\DL\lib\ssl.py", line 501, in wrap_socket
    return self.sslsocket_class._create(
  File "D:\Anaconda\envs\DL\lib\ssl.py", line 1074, in _create
    self.do_handshake()
  File "D:\Anaconda\envs\DL\lib\ssl.py", line 1343, in do_handshake
    self._sslobj.do_handshake()
urllib3.exceptions.ProtocolError: ('Connection aborted.', ConnectionResetError(10054, '远程主机强迫关闭了一个现有的连接。', None, 10054, None))

During handling of the above exception, another exception occurred:

Traceback (most recent call last):
  File "D:\Anaconda\envs\DL\lib\site-packages\wandb\sdk\internal\internal_api.py", line 2550, in upload_file
    response = self._upload_file_session.put(
  File "D:\Anaconda\envs\DL\lib\site-packages\requests\sessions.py", line 647, in put
    return self.request("PUT", url, data=data, **kwargs)
  File "D:\Anaconda\envs\DL\lib\site-packages\requests\sessions.py", line 587, in request
    resp = self.send(prep, **send_kwargs)
  File "D:\Anaconda\envs\DL\lib\site-packages\requests\sessions.py", line 701, in send
    r = adapter.send(request, **kwargs)
  File "D:\Anaconda\envs\DL\lib\site-packages\requests\adapters.py", line 547, in send
    raise ConnectionError(err, request=request)
requests.exceptions.ConnectionError: ('Connection aborted.', ConnectionResetError(10054, '远程主机强迫关闭了一个现有的连接。', None, 10054, None))

During handling of the above exception, another exception occurred:

Traceback (most recent call last):
  File "D:\Anaconda\envs\DL\lib\site-packages\wandb\sdk\lib\retry.py", line 131, in __call__
    result = self._call_fn(*args, **kwargs)
  File "D:\Anaconda\envs\DL\lib\site-packages\wandb\sdk\internal\internal_api.py", line 2581, in upload_file
    raise _e.with_traceback(sys.exc_info()[2])
  File "D:\Anaconda\envs\DL\lib\site-packages\wandb\sdk\internal\internal_api.py", line 2550, in upload_file
    response = self._upload_file_session.put(
  File "D:\Anaconda\envs\DL\lib\site-packages\requests\sessions.py", line 647, in put
    return self.request("PUT", url, data=data, **kwargs)
  File "D:\Anaconda\envs\DL\lib\site-packages\requests\sessions.py", line 587, in request
    resp = self.send(prep, **send_kwargs)
  File "D:\Anaconda\envs\DL\lib\site-packages\requests\sessions.py", line 701, in send
    r = adapter.send(request, **kwargs)
  File "D:\Anaconda\envs\DL\lib\site-packages\requests\adapters.py", line 547, in send
    raise ConnectionError(err, request=request)
wandb.sdk.lib.retry.TransientError: None
2024-05-17 10:57:46,792 INFO    Thread-16 :11840 [dir_watcher.py:_on_file_modified():288] file/dir modified: D:\Pycharm\ultralytics-main\wandb\run-20240517_105726-8s4xcs7t\files\output.log
2024-05-17 10:57:47,467 DEBUG   HandlerThread:11840 [handler.py:handle_request():146] handle_request: status_report
2024-05-17 10:57:47,686 ERROR   wandb-upload_0:11840 [internal_api.py:upload_file():2557] upload_file exception https://storage.googleapis.com/wandb-production.appspot.com/666233/runs/8s4xcs7t/wandb-metadata.json?Expires=1716001058&GoogleAccessId=gorilla-files-url-signer-man%40wandb-production.iam.gserviceaccount.com&Signature=ec329%2F0V3AAJRPiDl8T24eTHx%2F5eCf60h8pu0Zwhuhd1J9hoBYdundXmyO%2F9m4ij7eRPNJtcX2VI6fIiPHFTv6Ce2eb3pl9sVirFOqBFrq7Z3A%2FiT7ial%2B7uge0qIYnw3l%2Bl7GRP5XvPByp6jAEXKRayQWxzHK0BtR8Puj%2B2OsvbnUmKQDEv%2BrzrcKqZsC6Ao%2F5huX7AQ2wUDcFaYay4iRSk7%2FTj%2Fm9bH1cMVi%2BHhZARbdv8JI7DCDNGEjOohVTleqIgtbueSUmFQjsYD%2FWHNxTvlKoqxNM3hlkfocG29U%2B2s%2FhkCaSMGcqmK92LL83TEJpwwaN2xY4Nag9ql%2F6EgA%3D%3D: ('Connection aborted.', ConnectionResetError(10054, '远程主机强迫关闭了一个现有的连接。', None, 10054, None))
2024-05-17 10:57:47,686 ERROR   wandb-upload_0:11840 [internal_api.py:upload_file():2559] upload_file request headers: {'User-Agent': 'python-requests/2.28.2', 'Accept-Encoding': 'gzip, deflate', 'Accept': '*/*', 'Connection': 'keep-alive', 'Content-Length': '1195'}
2024-05-17 10:57:47,686 ERROR   wandb-upload_0:11840 [internal_api.py:upload_file():2561] upload_file response body: 
2024-05-17 10:57:48,799 INFO    Thread-16 :11840 [dir_watcher.py:_on_file_modified():288] file/dir modified: D:\Pycharm\ultralytics-main\wandb\run-20240517_105726-8s4xcs7t\files\output.log
2024-05-17 10:57:50,806 INFO    Thread-16 :11840 [dir_watcher.py:_on_file_modified():288] file/dir modified: D:\Pycharm\ultralytics-main\wandb\run-20240517_105726-8s4xcs7t\files\output.log
2024-05-17 10:57:52,719 DEBUG   HandlerThread:11840 [handler.py:handle_request():146] handle_request: status_report
2024-05-17 10:57:52,719 DEBUG   HandlerThread:11840 [handler.py:handle_request():146] handle_request: internal_messages
2024-05-17 10:57:52,735 DEBUG   HandlerThread:11840 [handler.py:handle_request():146] handle_request: stop_status
2024-05-17 10:57:52,735 DEBUG   SenderThread:11840 [sender.py:send_request():407] send_request: stop_status
2024-05-17 10:57:54,821 INFO    Thread-16 :11840 [dir_watcher.py:_on_file_modified():288] file/dir modified: D:\Pycharm\ultralytics-main\wandb\run-20240517_105726-8s4xcs7t\files\output.log
2024-05-17 10:57:56,828 INFO    Thread-16 :11840 [dir_watcher.py:_on_file_modified():288] file/dir modified: D:\Pycharm\ultralytics-main\wandb\run-20240517_105726-8s4xcs7t\files\output.log
