2024-05-20 09:59:02,691 INFO    StreamThr :62676 [internal.py:wandb_internal():86] W&B internal server running at pid: 62676, started at: 2024-05-20 09:59:02.691532
2024-05-20 09:59:02,692 DEBUG   HandlerThread:62676 [handler.py:handle_request():146] handle_request: status
2024-05-20 09:59:02,699 INFO    WriterThread:62676 [datastore.py:open_for_write():85] open: D:\Pycharm\ultralytics-main\wandb\run-20240520_095902-hb3qdudx\run-hb3qdudx.wandb
2024-05-20 09:59:02,700 DEBUG   SenderThread:62676 [sender.py:send():380] send: header
2024-05-20 09:59:02,704 DEBUG   SenderThread:62676 [sender.py:send():380] send: run
2024-05-20 09:59:03,544 INFO    SenderThread:62676 [dir_watcher.py:__init__():211] watching files in: D:\Pycharm\ultralytics-main\wandb\run-20240520_095902-hb3qdudx\files
2024-05-20 09:59:03,545 INFO    SenderThread:62676 [sender.py:_start_run_threads():1124] run started: hb3qdudx with start time 1716170342.692529
2024-05-20 09:59:03,557 DEBUG   HandlerThread:62676 [handler.py:handle_request():146] handle_request: check_version
2024-05-20 09:59:03,557 DEBUG   SenderThread:62676 [sender.py:send_request():407] send_request: check_version
2024-05-20 09:59:04,011 DEBUG   HandlerThread:62676 [handler.py:handle_request():146] handle_request: run_start
2024-05-20 09:59:04,061 DEBUG   HandlerThread:62676 [system_info.py:__init__():32] System info init
2024-05-20 09:59:04,061 DEBUG   HandlerThread:62676 [system_info.py:__init__():47] System info init done
2024-05-20 09:59:04,061 INFO    HandlerThread:62676 [system_monitor.py:start():194] Starting system monitor
2024-05-20 09:59:04,062 INFO    SystemMonitor:62676 [system_monitor.py:_start():158] Starting system asset monitoring threads
2024-05-20 09:59:04,062 INFO    HandlerThread:62676 [system_monitor.py:probe():214] Collecting system info
2024-05-20 09:59:04,074 INFO    SystemMonitor:62676 [interfaces.py:start():190] Started cpu monitoring
2024-05-20 09:59:04,076 INFO    SystemMonitor:62676 [interfaces.py:start():190] Started disk monitoring
2024-05-20 09:59:04,080 INFO    SystemMonitor:62676 [interfaces.py:start():190] Started gpu monitoring
2024-05-20 09:59:04,090 INFO    SystemMonitor:62676 [interfaces.py:start():190] Started memory monitoring
2024-05-20 09:59:04,096 DEBUG   HandlerThread:62676 [system_info.py:probe():196] Probing system
2024-05-20 09:59:04,116 INFO    SystemMonitor:62676 [interfaces.py:start():190] Started network monitoring
2024-05-20 09:59:04,117 DEBUG   HandlerThread:62676 [gitlib.py:_init_repo():56] git repository is invalid
2024-05-20 09:59:04,117 DEBUG   HandlerThread:62676 [system_info.py:probe():244] Probing system done
2024-05-20 09:59:04,117 DEBUG   HandlerThread:62676 [system_monitor.py:probe():223] {'os': 'Windows-10-10.0.22631-SP0', 'python': '3.9.18', 'heartbeatAt': '2024-05-20T01:59:04.096585', 'startedAt': '2024-05-20T01:59:02.675585', 'docker': None, 'cuda': None, 'args': (), 'state': 'running', 'program': 'D:\\Pycharm\\ultralytics-main\\train.py', 'codePathLocal': 'train.py', 'codePath': 'train.py', 'host': 'DESKTOP-VH2CUSJ', 'username': 'DELL', 'executable': 'D:\\Anaconda\\envs\\DL\\python.exe', 'cpu_count': 10, 'cpu_count_logical': 16, 'cpu_freq': {'current': 2400.0, 'min': 0.0, 'max': 2400.0}, 'cpu_freq_per_core': [{'current': 2400.0, 'min': 0.0, 'max': 2400.0}], 'disk': {'/': {'total': 244.13964462280273, 'used': 188.1594696044922}}, 'gpu': 'NVIDIA GeForce RTX 4050 Laptop GPU', 'gpu_count': 1, 'gpu_devices': [{'name': 'NVIDIA GeForce RTX 4050 Laptop GPU', 'memory_total': 6439305216}], 'memory': {'total': 15.692092895507812}}
2024-05-20 09:59:04,117 INFO    HandlerThread:62676 [system_monitor.py:probe():224] Finished collecting system info
2024-05-20 09:59:04,117 INFO    HandlerThread:62676 [system_monitor.py:probe():227] Publishing system info
2024-05-20 09:59:04,117 DEBUG   HandlerThread:62676 [system_info.py:_save_pip():52] Saving list of pip packages installed into the current environment
2024-05-20 09:59:04,118 DEBUG   HandlerThread:62676 [system_info.py:_save_pip():68] Saving pip packages done
2024-05-20 09:59:04,118 DEBUG   HandlerThread:62676 [system_info.py:_save_conda():75] Saving list of conda packages installed into the current environment
2024-05-20 09:59:04,557 INFO    Thread-16 :62676 [dir_watcher.py:_on_file_created():271] file/dir created: D:\Pycharm\ultralytics-main\wandb\run-20240520_095902-hb3qdudx\files\requirements.txt
2024-05-20 09:59:04,557 INFO    Thread-16 :62676 [dir_watcher.py:_on_file_created():271] file/dir created: D:\Pycharm\ultralytics-main\wandb\run-20240520_095902-hb3qdudx\files\conda-environment.yaml
2024-05-20 09:59:10,827 DEBUG   HandlerThread:62676 [system_info.py:_save_conda():87] Saving conda packages done
2024-05-20 09:59:10,828 INFO    HandlerThread:62676 [system_monitor.py:probe():229] Finished publishing system info
2024-05-20 09:59:10,845 DEBUG   HandlerThread:62676 [handler.py:handle_request():146] handle_request: status_report
2024-05-20 09:59:10,846 DEBUG   HandlerThread:62676 [handler.py:handle_request():146] handle_request: keepalive
2024-05-20 09:59:10,846 DEBUG   SenderThread:62676 [sender.py:send():380] send: files
2024-05-20 09:59:10,846 INFO    SenderThread:62676 [sender.py:_save_file():1380] saving file wandb-metadata.json with policy now
2024-05-20 09:59:10,858 DEBUG   HandlerThread:62676 [handler.py:handle_request():146] handle_request: stop_status
2024-05-20 09:59:10,859 DEBUG   HandlerThread:62676 [handler.py:handle_request():146] handle_request: internal_messages
2024-05-20 09:59:10,860 DEBUG   SenderThread:62676 [sender.py:send_request():407] send_request: stop_status
2024-05-20 09:59:11,525 DEBUG   SenderThread:62676 [sender.py:send():380] send: telemetry
2024-05-20 09:59:11,624 INFO    Thread-16 :62676 [dir_watcher.py:_on_file_modified():288] file/dir modified: D:\Pycharm\ultralytics-main\wandb\run-20240520_095902-hb3qdudx\files\conda-environment.yaml
2024-05-20 09:59:11,624 INFO    Thread-16 :62676 [dir_watcher.py:_on_file_created():271] file/dir created: D:\Pycharm\ultralytics-main\wandb\run-20240520_095902-hb3qdudx\files\output.log
2024-05-20 09:59:11,624 INFO    Thread-16 :62676 [dir_watcher.py:_on_file_created():271] file/dir created: D:\Pycharm\ultralytics-main\wandb\run-20240520_095902-hb3qdudx\files\wandb-metadata.json
2024-05-20 09:59:11,911 ERROR   wandb-upload_0:62676 [internal_api.py:upload_file():2557] upload_file exception https://storage.googleapis.com/wandb-production.appspot.com/666233/runs/hb3qdudx/wandb-metadata.json?Expires=1716256751&GoogleAccessId=gorilla-files-url-signer-man%40wandb-production.iam.gserviceaccount.com&Signature=RCpDAUVf6zEAMqHojgT9czUadROML9%2FgKLRBd9KQBCMaczGGzAgTlzyNaq%2BVQo2AT0GgIR4z46URIcRUR%2B9wYXhH7pRElBEsIbxfyKEwM4ye66GL2topKTqMEV0ico7C4EFxdFoLXjhtMa2MXpw2sPz8aRuencfH%2FpPMwqae8PkxzWa5PQ3tzfsbr57GRTnA6bo4PAQ5yuIB%2BCu%2Fouc8mUu9rwWDX1FdTb3Gmrvwcj2FcIoOvy1LITufykOHaZ%2FH%2BHF0ZQKkbPZlZe%2FzQ6E9r76Wn45QHUoGSzEp0d0eeZL5HGNaT9fvZ7J9uehYSLXbWJTCkvIIqHZWWFBf8zZoAg%3D%3D: ('Connection aborted.', ConnectionResetError(10054, '远程主机强迫关闭了一个现有的连接。', None, 10054, None))
2024-05-20 09:59:11,913 ERROR   wandb-upload_0:62676 [internal_api.py:upload_file():2559] upload_file request headers: {'User-Agent': 'python-requests/2.28.2', 'Accept-Encoding': 'gzip, deflate', 'Accept': '*/*', 'Connection': 'keep-alive', 'Content-Length': '1194'}
2024-05-20 09:59:11,913 ERROR   wandb-upload_0:62676 [internal_api.py:upload_file():2561] upload_file response body: 
2024-05-20 09:59:13,498 ERROR   wandb-upload_0:62676 [internal_api.py:upload_file():2557] upload_file exception https://storage.googleapis.com/wandb-production.appspot.com/666233/runs/hb3qdudx/wandb-metadata.json?Expires=1716256751&GoogleAccessId=gorilla-files-url-signer-man%40wandb-production.iam.gserviceaccount.com&Signature=RCpDAUVf6zEAMqHojgT9czUadROML9%2FgKLRBd9KQBCMaczGGzAgTlzyNaq%2BVQo2AT0GgIR4z46URIcRUR%2B9wYXhH7pRElBEsIbxfyKEwM4ye66GL2topKTqMEV0ico7C4EFxdFoLXjhtMa2MXpw2sPz8aRuencfH%2FpPMwqae8PkxzWa5PQ3tzfsbr57GRTnA6bo4PAQ5yuIB%2BCu%2Fouc8mUu9rwWDX1FdTb3Gmrvwcj2FcIoOvy1LITufykOHaZ%2FH%2BHF0ZQKkbPZlZe%2FzQ6E9r76Wn45QHUoGSzEp0d0eeZL5HGNaT9fvZ7J9uehYSLXbWJTCkvIIqHZWWFBf8zZoAg%3D%3D: ('Connection aborted.', ConnectionResetError(10054, '远程主机强迫关闭了一个现有的连接。', None, 10054, None))
2024-05-20 09:59:13,498 ERROR   wandb-upload_0:62676 [internal_api.py:upload_file():2559] upload_file request headers: {'User-Agent': 'python-requests/2.28.2', 'Accept-Encoding': 'gzip, deflate', 'Accept': '*/*', 'Connection': 'keep-alive', 'Content-Length': '1194'}
2024-05-20 09:59:13,499 ERROR   wandb-upload_0:62676 [internal_api.py:upload_file():2561] upload_file response body: 
2024-05-20 09:59:13,550 DEBUG   HandlerThread:62676 [handler.py:handle_request():146] handle_request: status_report
2024-05-20 09:59:13,636 INFO    Thread-16 :62676 [dir_watcher.py:_on_file_modified():288] file/dir modified: D:\Pycharm\ultralytics-main\wandb\run-20240520_095902-hb3qdudx\files\output.log
2024-05-20 09:59:16,423 ERROR   wandb-upload_0:62676 [internal_api.py:upload_file():2557] upload_file exception https://storage.googleapis.com/wandb-production.appspot.com/666233/runs/hb3qdudx/wandb-metadata.json?Expires=1716256751&GoogleAccessId=gorilla-files-url-signer-man%40wandb-production.iam.gserviceaccount.com&Signature=RCpDAUVf6zEAMqHojgT9czUadROML9%2FgKLRBd9KQBCMaczGGzAgTlzyNaq%2BVQo2AT0GgIR4z46URIcRUR%2B9wYXhH7pRElBEsIbxfyKEwM4ye66GL2topKTqMEV0ico7C4EFxdFoLXjhtMa2MXpw2sPz8aRuencfH%2FpPMwqae8PkxzWa5PQ3tzfsbr57GRTnA6bo4PAQ5yuIB%2BCu%2Fouc8mUu9rwWDX1FdTb3Gmrvwcj2FcIoOvy1LITufykOHaZ%2FH%2BHF0ZQKkbPZlZe%2FzQ6E9r76Wn45QHUoGSzEp0d0eeZL5HGNaT9fvZ7J9uehYSLXbWJTCkvIIqHZWWFBf8zZoAg%3D%3D: ('Connection aborted.', ConnectionResetError(10054, '远程主机强迫关闭了一个现有的连接。', None, 10054, None))
2024-05-20 09:59:16,423 ERROR   wandb-upload_0:62676 [internal_api.py:upload_file():2559] upload_file request headers: {'User-Agent': 'python-requests/2.28.2', 'Accept-Encoding': 'gzip, deflate', 'Accept': '*/*', 'Connection': 'keep-alive', 'Content-Length': '1194'}
2024-05-20 09:59:16,423 ERROR   wandb-upload_0:62676 [internal_api.py:upload_file():2561] upload_file response body: 
2024-05-20 09:59:16,423 INFO    wandb-upload_0:62676 [retry.py:__call__():172] Retry attempt failed:
Traceback (most recent call last):
  File "D:\Anaconda\envs\DL\lib\site-packages\urllib3\connectionpool.py", line 715, in urlopen
    httplib_response = self._make_request(
  File "D:\Anaconda\envs\DL\lib\site-packages\urllib3\connectionpool.py", line 404, in _make_request
    self._validate_conn(conn)
  File "D:\Anaconda\envs\DL\lib\site-packages\urllib3\connectionpool.py", line 1058, in _validate_conn
    conn.connect()
  File "D:\Anaconda\envs\DL\lib\site-packages\urllib3\connection.py", line 419, in connect
    self.sock = ssl_wrap_socket(
  File "D:\Anaconda\envs\DL\lib\site-packages\urllib3\util\ssl_.py", line 449, in ssl_wrap_socket
    ssl_sock = _ssl_wrap_socket_impl(
  File "D:\Anaconda\envs\DL\lib\site-packages\urllib3\util\ssl_.py", line 493, in _ssl_wrap_socket_impl
    return ssl_context.wrap_socket(sock, server_hostname=server_hostname)
  File "D:\Anaconda\envs\DL\lib\ssl.py", line 501, in wrap_socket
    return self.sslsocket_class._create(
  File "D:\Anaconda\envs\DL\lib\ssl.py", line 1074, in _create
    self.do_handshake()
  File "D:\Anaconda\envs\DL\lib\ssl.py", line 1343, in do_handshake
    self._sslobj.do_handshake()
ConnectionResetError: [WinError 10054] 远程主机强迫关闭了一个现有的连接。

During handling of the above exception, another exception occurred:

Traceback (most recent call last):
  File "D:\Anaconda\envs\DL\lib\site-packages\requests\adapters.py", line 489, in send
    resp = conn.urlopen(
  File "D:\Anaconda\envs\DL\lib\site-packages\urllib3\connectionpool.py", line 799, in urlopen
    retries = retries.increment(
  File "D:\Anaconda\envs\DL\lib\site-packages\urllib3\util\retry.py", line 550, in increment
    raise six.reraise(type(error), error, _stacktrace)
  File "D:\Anaconda\envs\DL\lib\site-packages\urllib3\packages\six.py", line 769, in reraise
    raise value.with_traceback(tb)
  File "D:\Anaconda\envs\DL\lib\site-packages\urllib3\connectionpool.py", line 715, in urlopen
    httplib_response = self._make_request(
  File "D:\Anaconda\envs\DL\lib\site-packages\urllib3\connectionpool.py", line 404, in _make_request
    self._validate_conn(conn)
  File "D:\Anaconda\envs\DL\lib\site-packages\urllib3\connectionpool.py", line 1058, in _validate_conn
    conn.connect()
  File "D:\Anaconda\envs\DL\lib\site-packages\urllib3\connection.py", line 419, in connect
    self.sock = ssl_wrap_socket(
  File "D:\Anaconda\envs\DL\lib\site-packages\urllib3\util\ssl_.py", line 449, in ssl_wrap_socket
    ssl_sock = _ssl_wrap_socket_impl(
  File "D:\Anaconda\envs\DL\lib\site-packages\urllib3\util\ssl_.py", line 493, in _ssl_wrap_socket_impl
    return ssl_context.wrap_socket(sock, server_hostname=server_hostname)
  File "D:\Anaconda\envs\DL\lib\ssl.py", line 501, in wrap_socket
    return self.sslsocket_class._create(
  File "D:\Anaconda\envs\DL\lib\ssl.py", line 1074, in _create
    self.do_handshake()
  File "D:\Anaconda\envs\DL\lib\ssl.py", line 1343, in do_handshake
    self._sslobj.do_handshake()
urllib3.exceptions.ProtocolError: ('Connection aborted.', ConnectionResetError(10054, '远程主机强迫关闭了一个现有的连接。', None, 10054, None))

During handling of the above exception, another exception occurred:

Traceback (most recent call last):
  File "D:\Anaconda\envs\DL\lib\site-packages\wandb\sdk\internal\internal_api.py", line 2550, in upload_file
    response = self._upload_file_session.put(
  File "D:\Anaconda\envs\DL\lib\site-packages\requests\sessions.py", line 647, in put
    return self.request("PUT", url, data=data, **kwargs)
  File "D:\Anaconda\envs\DL\lib\site-packages\requests\sessions.py", line 587, in request
    resp = self.send(prep, **send_kwargs)
  File "D:\Anaconda\envs\DL\lib\site-packages\requests\sessions.py", line 701, in send
    r = adapter.send(request, **kwargs)
  File "D:\Anaconda\envs\DL\lib\site-packages\requests\adapters.py", line 547, in send
    raise ConnectionError(err, request=request)
requests.exceptions.ConnectionError: ('Connection aborted.', ConnectionResetError(10054, '远程主机强迫关闭了一个现有的连接。', None, 10054, None))

During handling of the above exception, another exception occurred:

Traceback (most recent call last):
  File "D:\Anaconda\envs\DL\lib\site-packages\wandb\sdk\lib\retry.py", line 131, in __call__
    result = self._call_fn(*args, **kwargs)
  File "D:\Anaconda\envs\DL\lib\site-packages\wandb\sdk\internal\internal_api.py", line 2581, in upload_file
    raise _e.with_traceback(sys.exc_info()[2])
  File "D:\Anaconda\envs\DL\lib\site-packages\wandb\sdk\internal\internal_api.py", line 2550, in upload_file
    response = self._upload_file_session.put(
  File "D:\Anaconda\envs\DL\lib\site-packages\requests\sessions.py", line 647, in put
    return self.request("PUT", url, data=data, **kwargs)
  File "D:\Anaconda\envs\DL\lib\site-packages\requests\sessions.py", line 587, in request
    resp = self.send(prep, **send_kwargs)
  File "D:\Anaconda\envs\DL\lib\site-packages\requests\sessions.py", line 701, in send
    r = adapter.send(request, **kwargs)
  File "D:\Anaconda\envs\DL\lib\site-packages\requests\adapters.py", line 547, in send
    raise ConnectionError(err, request=request)
wandb.sdk.lib.retry.TransientError: None
2024-05-20 09:59:18,587 DEBUG   HandlerThread:62676 [handler.py:handle_request():146] handle_request: status_report
2024-05-20 09:59:21,832 ERROR   wandb-upload_0:62676 [internal_api.py:upload_file():2557] upload_file exception https://storage.googleapis.com/wandb-production.appspot.com/666233/runs/hb3qdudx/wandb-metadata.json?Expires=1716256751&GoogleAccessId=gorilla-files-url-signer-man%40wandb-production.iam.gserviceaccount.com&Signature=RCpDAUVf6zEAMqHojgT9czUadROML9%2FgKLRBd9KQBCMaczGGzAgTlzyNaq%2BVQo2AT0GgIR4z46URIcRUR%2B9wYXhH7pRElBEsIbxfyKEwM4ye66GL2topKTqMEV0ico7C4EFxdFoLXjhtMa2MXpw2sPz8aRuencfH%2FpPMwqae8PkxzWa5PQ3tzfsbr57GRTnA6bo4PAQ5yuIB%2BCu%2Fouc8mUu9rwWDX1FdTb3Gmrvwcj2FcIoOvy1LITufykOHaZ%2FH%2BHF0ZQKkbPZlZe%2FzQ6E9r76Wn45QHUoGSzEp0d0eeZL5HGNaT9fvZ7J9uehYSLXbWJTCkvIIqHZWWFBf8zZoAg%3D%3D: ('Connection aborted.', ConnectionResetError(10054, '远程主机强迫关闭了一个现有的连接。', None, 10054, None))
2024-05-20 09:59:21,834 ERROR   wandb-upload_0:62676 [internal_api.py:upload_file():2559] upload_file request headers: {'User-Agent': 'python-requests/2.28.2', 'Accept-Encoding': 'gzip, deflate', 'Accept': '*/*', 'Connection': 'keep-alive', 'Content-Length': '1194'}
2024-05-20 09:59:21,834 ERROR   wandb-upload_0:62676 [internal_api.py:upload_file():2561] upload_file response body: 
2024-05-20 09:59:23,624 DEBUG   HandlerThread:62676 [handler.py:handle_request():146] handle_request: status_report
2024-05-20 09:59:25,750 INFO    Thread-16 :62676 [dir_watcher.py:_on_file_modified():288] file/dir modified: D:\Pycharm\ultralytics-main\wandb\run-20240520_095902-hb3qdudx\files\output.log
2024-05-20 09:59:25,889 DEBUG   HandlerThread:62676 [handler.py:handle_request():146] handle_request: stop_status
2024-05-20 09:59:25,890 DEBUG   SenderThread:62676 [sender.py:send_request():407] send_request: stop_status
2024-05-20 09:59:25,890 DEBUG   HandlerThread:62676 [handler.py:handle_request():146] handle_request: internal_messages
2024-05-20 09:59:27,769 INFO    Thread-16 :62676 [dir_watcher.py:_on_file_modified():288] file/dir modified: D:\Pycharm\ultralytics-main\wandb\run-20240520_095902-hb3qdudx\files\output.log
2024-05-20 09:59:28,642 DEBUG   HandlerThread:62676 [handler.py:handle_request():146] handle_request: status_report
2024-05-20 09:59:29,786 INFO    Thread-16 :62676 [dir_watcher.py:_on_file_modified():288] file/dir modified: D:\Pycharm\ultralytics-main\wandb\run-20240520_095902-hb3qdudx\files\output.log
2024-05-20 09:59:31,575 ERROR   wandb-upload_0:62676 [internal_api.py:upload_file():2557] upload_file exception https://storage.googleapis.com/wandb-production.appspot.com/666233/runs/hb3qdudx/wandb-metadata.json?Expires=1716256751&GoogleAccessId=gorilla-files-url-signer-man%40wandb-production.iam.gserviceaccount.com&Signature=RCpDAUVf6zEAMqHojgT9czUadROML9%2FgKLRBd9KQBCMaczGGzAgTlzyNaq%2BVQo2AT0GgIR4z46URIcRUR%2B9wYXhH7pRElBEsIbxfyKEwM4ye66GL2topKTqMEV0ico7C4EFxdFoLXjhtMa2MXpw2sPz8aRuencfH%2FpPMwqae8PkxzWa5PQ3tzfsbr57GRTnA6bo4PAQ5yuIB%2BCu%2Fouc8mUu9rwWDX1FdTb3Gmrvwcj2FcIoOvy1LITufykOHaZ%2FH%2BHF0ZQKkbPZlZe%2FzQ6E9r76Wn45QHUoGSzEp0d0eeZL5HGNaT9fvZ7J9uehYSLXbWJTCkvIIqHZWWFBf8zZoAg%3D%3D: ('Connection aborted.', ConnectionResetError(10054, '远程主机强迫关闭了一个现有的连接。', None, 10054, None))
2024-05-20 09:59:31,575 ERROR   wandb-upload_0:62676 [internal_api.py:upload_file():2559] upload_file request headers: {'User-Agent': 'python-requests/2.28.2', 'Accept-Encoding': 'gzip, deflate', 'Accept': '*/*', 'Connection': 'keep-alive', 'Content-Length': '1194'}
2024-05-20 09:59:31,575 ERROR   wandb-upload_0:62676 [internal_api.py:upload_file():2561] upload_file response body: 
2024-05-20 09:59:31,814 INFO    Thread-16 :62676 [dir_watcher.py:_on_file_modified():288] file/dir modified: D:\Pycharm\ultralytics-main\wandb\run-20240520_095902-hb3qdudx\files\output.log
2024-05-20 09:59:33,826 INFO    Thread-16 :62676 [dir_watcher.py:_on_file_modified():288] file/dir modified: D:\Pycharm\ultralytics-main\wandb\run-20240520_095902-hb3qdudx\files\output.log
2024-05-20 09:59:33,888 DEBUG   HandlerThread:62676 [handler.py:handle_request():146] handle_request: status_report
2024-05-20 09:59:34,838 INFO    Thread-16 :62676 [dir_watcher.py:_on_file_modified():288] file/dir modified: D:\Pycharm\ultralytics-main\wandb\run-20240520_095902-hb3qdudx\files\config.yaml
2024-05-20 09:59:37,869 INFO    Thread-16 :62676 [dir_watcher.py:_on_file_modified():288] file/dir modified: D:\Pycharm\ultralytics-main\wandb\run-20240520_095902-hb3qdudx\files\output.log
2024-05-20 09:59:39,180 DEBUG   HandlerThread:62676 [handler.py:handle_request():146] handle_request: status_report
2024-05-20 09:59:39,886 INFO    Thread-16 :62676 [dir_watcher.py:_on_file_modified():288] file/dir modified: D:\Pycharm\ultralytics-main\wandb\run-20240520_095902-hb3qdudx\files\output.log
