2024-05-15 16:53:19,155 INFO    StreamThr :15772 [internal.py:wandb_internal():86] W&B internal server running at pid: 15772, started at: 2024-05-15 16:53:19.154958
2024-05-15 16:53:19,158 DEBUG   HandlerThread:15772 [handler.py:handle_request():146] handle_request: status
2024-05-15 16:53:19,159 INFO    WriterThread:15772 [datastore.py:open_for_write():85] open: D:\Pycharm\ultralytics-main\wandb\run-20240515_165319-i3koqsy0\run-i3koqsy0.wandb
2024-05-15 16:53:19,160 DEBUG   SenderThread:15772 [sender.py:send():380] send: header
2024-05-15 16:53:19,161 DEBUG   SenderThread:15772 [sender.py:send():380] send: run
2024-05-15 16:53:19,944 INFO    SenderThread:15772 [dir_watcher.py:__init__():211] watching files in: D:\Pycharm\ultralytics-main\wandb\run-20240515_165319-i3koqsy0\files
2024-05-15 16:53:19,944 INFO    SenderThread:15772 [sender.py:_start_run_threads():1124] run started: i3koqsy0 with start time 1715763199.156957
2024-05-15 16:53:19,949 DEBUG   HandlerThread:15772 [handler.py:handle_request():146] handle_request: check_version
2024-05-15 16:53:19,949 DEBUG   SenderThread:15772 [sender.py:send_request():407] send_request: check_version
2024-05-15 16:53:20,628 DEBUG   HandlerThread:15772 [handler.py:handle_request():146] handle_request: run_start
2024-05-15 16:53:20,659 DEBUG   HandlerThread:15772 [system_info.py:__init__():32] System info init
2024-05-15 16:53:20,659 DEBUG   HandlerThread:15772 [system_info.py:__init__():47] System info init done
2024-05-15 16:53:20,659 INFO    HandlerThread:15772 [system_monitor.py:start():194] Starting system monitor
2024-05-15 16:53:20,660 INFO    SystemMonitor:15772 [system_monitor.py:_start():158] Starting system asset monitoring threads
2024-05-15 16:53:20,660 INFO    HandlerThread:15772 [system_monitor.py:probe():214] Collecting system info
2024-05-15 16:53:20,665 INFO    SystemMonitor:15772 [interfaces.py:start():190] Started cpu monitoring
2024-05-15 16:53:20,666 INFO    SystemMonitor:15772 [interfaces.py:start():190] Started disk monitoring
2024-05-15 16:53:20,666 INFO    SystemMonitor:15772 [interfaces.py:start():190] Started gpu monitoring
2024-05-15 16:53:20,674 INFO    SystemMonitor:15772 [interfaces.py:start():190] Started memory monitoring
2024-05-15 16:53:20,683 INFO    SystemMonitor:15772 [interfaces.py:start():190] Started network monitoring
2024-05-15 16:53:20,688 DEBUG   HandlerThread:15772 [system_info.py:probe():196] Probing system
2024-05-15 16:53:20,689 DEBUG   HandlerThread:15772 [gitlib.py:_init_repo():56] git repository is invalid
2024-05-15 16:53:20,689 DEBUG   HandlerThread:15772 [system_info.py:probe():244] Probing system done
2024-05-15 16:53:20,689 DEBUG   HandlerThread:15772 [system_monitor.py:probe():223] {'os': 'Windows-10-10.0.22631-SP0', 'python': '3.9.18', 'heartbeatAt': '2024-05-15T08:53:20.688703', 'startedAt': '2024-05-15T08:53:19.133958', 'docker': None, 'cuda': None, 'args': (), 'state': 'running', 'program': 'D:\\Pycharm\\ultralytics-main\\train.py', 'codePathLocal': 'train.py', 'codePath': 'train.py', 'host': 'DESKTOP-VH2CUSJ', 'username': 'DELL', 'executable': 'D:\\Anaconda\\envs\\DL\\python.exe', 'cpu_count': 10, 'cpu_count_logical': 16, 'cpu_freq': {'current': 2400.0, 'min': 0.0, 'max': 2400.0}, 'cpu_freq_per_core': [{'current': 2400.0, 'min': 0.0, 'max': 2400.0}], 'disk': {'/': {'total': 244.13964462280273, 'used': 170.84112548828125}}, 'gpu': 'NVIDIA GeForce RTX 4050 Laptop GPU', 'gpu_count': 1, 'gpu_devices': [{'name': 'NVIDIA GeForce RTX 4050 Laptop GPU', 'memory_total': 6439305216}], 'memory': {'total': 15.692092895507812}}
2024-05-15 16:53:20,689 INFO    HandlerThread:15772 [system_monitor.py:probe():224] Finished collecting system info
2024-05-15 16:53:20,689 INFO    HandlerThread:15772 [system_monitor.py:probe():227] Publishing system info
2024-05-15 16:53:20,689 DEBUG   HandlerThread:15772 [system_info.py:_save_pip():52] Saving list of pip packages installed into the current environment
2024-05-15 16:53:20,690 DEBUG   HandlerThread:15772 [system_info.py:_save_pip():68] Saving pip packages done
2024-05-15 16:53:20,690 DEBUG   HandlerThread:15772 [system_info.py:_save_conda():75] Saving list of conda packages installed into the current environment
2024-05-15 16:53:20,949 INFO    Thread-16 :15772 [dir_watcher.py:_on_file_created():271] file/dir created: D:\Pycharm\ultralytics-main\wandb\run-20240515_165319-i3koqsy0\files\requirements.txt
2024-05-15 16:53:20,949 INFO    Thread-16 :15772 [dir_watcher.py:_on_file_created():271] file/dir created: D:\Pycharm\ultralytics-main\wandb\run-20240515_165319-i3koqsy0\files\conda-environment.yaml
2024-05-15 16:53:26,491 DEBUG   HandlerThread:15772 [system_info.py:_save_conda():87] Saving conda packages done
2024-05-15 16:53:26,493 INFO    HandlerThread:15772 [system_monitor.py:probe():229] Finished publishing system info
2024-05-15 16:53:26,504 DEBUG   HandlerThread:15772 [handler.py:handle_request():146] handle_request: status_report
2024-05-15 16:53:26,504 DEBUG   HandlerThread:15772 [handler.py:handle_request():146] handle_request: keepalive
2024-05-15 16:53:26,504 DEBUG   SenderThread:15772 [sender.py:send():380] send: files
2024-05-15 16:53:26,504 INFO    SenderThread:15772 [sender.py:_save_file():1380] saving file wandb-metadata.json with policy now
2024-05-15 16:53:26,510 DEBUG   HandlerThread:15772 [handler.py:handle_request():146] handle_request: stop_status
2024-05-15 16:53:26,510 DEBUG   SenderThread:15772 [sender.py:send_request():407] send_request: stop_status
2024-05-15 16:53:26,511 DEBUG   HandlerThread:15772 [handler.py:handle_request():146] handle_request: internal_messages
2024-05-15 16:53:26,745 DEBUG   SenderThread:15772 [sender.py:send():380] send: telemetry
2024-05-15 16:53:27,019 INFO    Thread-16 :15772 [dir_watcher.py:_on_file_modified():288] file/dir modified: D:\Pycharm\ultralytics-main\wandb\run-20240515_165319-i3koqsy0\files\conda-environment.yaml
2024-05-15 16:53:27,019 INFO    Thread-16 :15772 [dir_watcher.py:_on_file_created():271] file/dir created: D:\Pycharm\ultralytics-main\wandb\run-20240515_165319-i3koqsy0\files\wandb-metadata.json
2024-05-15 16:53:27,019 INFO    Thread-16 :15772 [dir_watcher.py:_on_file_created():271] file/dir created: D:\Pycharm\ultralytics-main\wandb\run-20240515_165319-i3koqsy0\files\output.log
2024-05-15 16:53:27,465 ERROR   wandb-upload_0:15772 [internal_api.py:upload_file():2557] upload_file exception https://storage.googleapis.com/wandb-production.appspot.com/666233/runs/i3koqsy0/wandb-metadata.json?Expires=1715849607&GoogleAccessId=gorilla-files-url-signer-man%40wandb-production.iam.gserviceaccount.com&Signature=I8ePYaZOwyI8zZPA4tahnlEYExo0t1IrHPFCVYc4uOqLrmyfPP0KB5TVuXw%2FPX3wl1HLBjSRfk8%2FMUUPbq18n3y2sXOJkLawRZgxKdaPHBiZQX4CwK0LLX0m4lZ1%2F85dvZaw%2F3uj2xpFkd1nUNNyc6XsGvdfWfiKM7oG3x1kvazsA7qQ5QUlKldrLMVPs4m2s95tKlR6u7rKV3H%2BWuvLnwVDwgiiT4QfdL3Dd5iQ%2BagRZl2Uuc6FnW3r04q5%2BOokVpJVqy9AkyKtN%2By%2FSuXGzL7pB9JKyEXTaCzP6clq06f9VIvLLCI%2FIZ9x79t%2Bt1EeVjTjuiYDg3UhLLGpRBPHlw%3D%3D: ('Connection aborted.', ConnectionResetError(10054, '远程主机强迫关闭了一个现有的连接。', None, 10054, None))
2024-05-15 16:53:27,470 ERROR   wandb-upload_0:15772 [internal_api.py:upload_file():2559] upload_file request headers: {'User-Agent': 'python-requests/2.28.2', 'Accept-Encoding': 'gzip, deflate', 'Accept': '*/*', 'Connection': 'keep-alive', 'Content-Length': '1195'}
2024-05-15 16:53:27,470 ERROR   wandb-upload_0:15772 [internal_api.py:upload_file():2561] upload_file response body: 
2024-05-15 16:53:28,800 ERROR   wandb-upload_0:15772 [internal_api.py:upload_file():2557] upload_file exception https://storage.googleapis.com/wandb-production.appspot.com/666233/runs/i3koqsy0/wandb-metadata.json?Expires=1715849607&GoogleAccessId=gorilla-files-url-signer-man%40wandb-production.iam.gserviceaccount.com&Signature=I8ePYaZOwyI8zZPA4tahnlEYExo0t1IrHPFCVYc4uOqLrmyfPP0KB5TVuXw%2FPX3wl1HLBjSRfk8%2FMUUPbq18n3y2sXOJkLawRZgxKdaPHBiZQX4CwK0LLX0m4lZ1%2F85dvZaw%2F3uj2xpFkd1nUNNyc6XsGvdfWfiKM7oG3x1kvazsA7qQ5QUlKldrLMVPs4m2s95tKlR6u7rKV3H%2BWuvLnwVDwgiiT4QfdL3Dd5iQ%2BagRZl2Uuc6FnW3r04q5%2BOokVpJVqy9AkyKtN%2By%2FSuXGzL7pB9JKyEXTaCzP6clq06f9VIvLLCI%2FIZ9x79t%2Bt1EeVjTjuiYDg3UhLLGpRBPHlw%3D%3D: ('Connection aborted.', ConnectionResetError(10054, '远程主机强迫关闭了一个现有的连接。', None, 10054, None))
2024-05-15 16:53:28,800 ERROR   wandb-upload_0:15772 [internal_api.py:upload_file():2559] upload_file request headers: {'User-Agent': 'python-requests/2.28.2', 'Accept-Encoding': 'gzip, deflate', 'Accept': '*/*', 'Connection': 'keep-alive', 'Content-Length': '1195'}
2024-05-15 16:53:28,800 ERROR   wandb-upload_0:15772 [internal_api.py:upload_file():2561] upload_file response body: 
2024-05-15 16:53:29,035 INFO    Thread-16 :15772 [dir_watcher.py:_on_file_modified():288] file/dir modified: D:\Pycharm\ultralytics-main\wandb\run-20240515_165319-i3koqsy0\files\output.log
2024-05-15 16:53:29,768 DEBUG   HandlerThread:15772 [handler.py:handle_request():146] handle_request: status_report
2024-05-15 16:53:31,398 ERROR   wandb-upload_0:15772 [internal_api.py:upload_file():2557] upload_file exception https://storage.googleapis.com/wandb-production.appspot.com/666233/runs/i3koqsy0/wandb-metadata.json?Expires=1715849607&GoogleAccessId=gorilla-files-url-signer-man%40wandb-production.iam.gserviceaccount.com&Signature=I8ePYaZOwyI8zZPA4tahnlEYExo0t1IrHPFCVYc4uOqLrmyfPP0KB5TVuXw%2FPX3wl1HLBjSRfk8%2FMUUPbq18n3y2sXOJkLawRZgxKdaPHBiZQX4CwK0LLX0m4lZ1%2F85dvZaw%2F3uj2xpFkd1nUNNyc6XsGvdfWfiKM7oG3x1kvazsA7qQ5QUlKldrLMVPs4m2s95tKlR6u7rKV3H%2BWuvLnwVDwgiiT4QfdL3Dd5iQ%2BagRZl2Uuc6FnW3r04q5%2BOokVpJVqy9AkyKtN%2By%2FSuXGzL7pB9JKyEXTaCzP6clq06f9VIvLLCI%2FIZ9x79t%2Bt1EeVjTjuiYDg3UhLLGpRBPHlw%3D%3D: ('Connection aborted.', ConnectionResetError(10054, '远程主机强迫关闭了一个现有的连接。', None, 10054, None))
2024-05-15 16:53:31,399 ERROR   wandb-upload_0:15772 [internal_api.py:upload_file():2559] upload_file request headers: {'User-Agent': 'python-requests/2.28.2', 'Accept-Encoding': 'gzip, deflate', 'Accept': '*/*', 'Connection': 'keep-alive', 'Content-Length': '1195'}
2024-05-15 16:53:31,399 ERROR   wandb-upload_0:15772 [internal_api.py:upload_file():2561] upload_file response body: 
2024-05-15 16:53:31,399 INFO    wandb-upload_0:15772 [retry.py:__call__():172] Retry attempt failed:
Traceback (most recent call last):
  File "D:\Anaconda\envs\DL\lib\site-packages\urllib3\connectionpool.py", line 715, in urlopen
    httplib_response = self._make_request(
  File "D:\Anaconda\envs\DL\lib\site-packages\urllib3\connectionpool.py", line 404, in _make_request
    self._validate_conn(conn)
  File "D:\Anaconda\envs\DL\lib\site-packages\urllib3\connectionpool.py", line 1058, in _validate_conn
    conn.connect()
  File "D:\Anaconda\envs\DL\lib\site-packages\urllib3\connection.py", line 419, in connect
    self.sock = ssl_wrap_socket(
  File "D:\Anaconda\envs\DL\lib\site-packages\urllib3\util\ssl_.py", line 449, in ssl_wrap_socket
    ssl_sock = _ssl_wrap_socket_impl(
  File "D:\Anaconda\envs\DL\lib\site-packages\urllib3\util\ssl_.py", line 493, in _ssl_wrap_socket_impl
    return ssl_context.wrap_socket(sock, server_hostname=server_hostname)
  File "D:\Anaconda\envs\DL\lib\ssl.py", line 501, in wrap_socket
    return self.sslsocket_class._create(
  File "D:\Anaconda\envs\DL\lib\ssl.py", line 1074, in _create
    self.do_handshake()
  File "D:\Anaconda\envs\DL\lib\ssl.py", line 1343, in do_handshake
    self._sslobj.do_handshake()
ConnectionResetError: [WinError 10054] 远程主机强迫关闭了一个现有的连接。

During handling of the above exception, another exception occurred:

Traceback (most recent call last):
  File "D:\Anaconda\envs\DL\lib\site-packages\requests\adapters.py", line 489, in send
    resp = conn.urlopen(
  File "D:\Anaconda\envs\DL\lib\site-packages\urllib3\connectionpool.py", line 799, in urlopen
    retries = retries.increment(
  File "D:\Anaconda\envs\DL\lib\site-packages\urllib3\util\retry.py", line 550, in increment
    raise six.reraise(type(error), error, _stacktrace)
  File "D:\Anaconda\envs\DL\lib\site-packages\urllib3\packages\six.py", line 769, in reraise
    raise value.with_traceback(tb)
  File "D:\Anaconda\envs\DL\lib\site-packages\urllib3\connectionpool.py", line 715, in urlopen
    httplib_response = self._make_request(
  File "D:\Anaconda\envs\DL\lib\site-packages\urllib3\connectionpool.py", line 404, in _make_request
    self._validate_conn(conn)
  File "D:\Anaconda\envs\DL\lib\site-packages\urllib3\connectionpool.py", line 1058, in _validate_conn
    conn.connect()
  File "D:\Anaconda\envs\DL\lib\site-packages\urllib3\connection.py", line 419, in connect
    self.sock = ssl_wrap_socket(
  File "D:\Anaconda\envs\DL\lib\site-packages\urllib3\util\ssl_.py", line 449, in ssl_wrap_socket
    ssl_sock = _ssl_wrap_socket_impl(
  File "D:\Anaconda\envs\DL\lib\site-packages\urllib3\util\ssl_.py", line 493, in _ssl_wrap_socket_impl
    return ssl_context.wrap_socket(sock, server_hostname=server_hostname)
  File "D:\Anaconda\envs\DL\lib\ssl.py", line 501, in wrap_socket
    return self.sslsocket_class._create(
  File "D:\Anaconda\envs\DL\lib\ssl.py", line 1074, in _create
    self.do_handshake()
  File "D:\Anaconda\envs\DL\lib\ssl.py", line 1343, in do_handshake
    self._sslobj.do_handshake()
urllib3.exceptions.ProtocolError: ('Connection aborted.', ConnectionResetError(10054, '远程主机强迫关闭了一个现有的连接。', None, 10054, None))

During handling of the above exception, another exception occurred:

Traceback (most recent call last):
  File "D:\Anaconda\envs\DL\lib\site-packages\wandb\sdk\internal\internal_api.py", line 2550, in upload_file
    response = self._upload_file_session.put(
  File "D:\Anaconda\envs\DL\lib\site-packages\requests\sessions.py", line 647, in put
    return self.request("PUT", url, data=data, **kwargs)
  File "D:\Anaconda\envs\DL\lib\site-packages\requests\sessions.py", line 587, in request
    resp = self.send(prep, **send_kwargs)
  File "D:\Anaconda\envs\DL\lib\site-packages\requests\sessions.py", line 701, in send
    r = adapter.send(request, **kwargs)
  File "D:\Anaconda\envs\DL\lib\site-packages\requests\adapters.py", line 547, in send
    raise ConnectionError(err, request=request)
requests.exceptions.ConnectionError: ('Connection aborted.', ConnectionResetError(10054, '远程主机强迫关闭了一个现有的连接。', None, 10054, None))

During handling of the above exception, another exception occurred:

Traceback (most recent call last):
  File "D:\Anaconda\envs\DL\lib\site-packages\wandb\sdk\lib\retry.py", line 131, in __call__
    result = self._call_fn(*args, **kwargs)
  File "D:\Anaconda\envs\DL\lib\site-packages\wandb\sdk\internal\internal_api.py", line 2581, in upload_file
    raise _e.with_traceback(sys.exc_info()[2])
  File "D:\Anaconda\envs\DL\lib\site-packages\wandb\sdk\internal\internal_api.py", line 2550, in upload_file
    response = self._upload_file_session.put(
  File "D:\Anaconda\envs\DL\lib\site-packages\requests\sessions.py", line 647, in put
    return self.request("PUT", url, data=data, **kwargs)
  File "D:\Anaconda\envs\DL\lib\site-packages\requests\sessions.py", line 587, in request
    resp = self.send(prep, **send_kwargs)
  File "D:\Anaconda\envs\DL\lib\site-packages\requests\sessions.py", line 701, in send
    r = adapter.send(request, **kwargs)
  File "D:\Anaconda\envs\DL\lib\site-packages\requests\adapters.py", line 547, in send
    raise ConnectionError(err, request=request)
wandb.sdk.lib.retry.TransientError: None
2024-05-15 16:53:33,074 INFO    Thread-16 :15772 [dir_watcher.py:_on_file_modified():288] file/dir modified: D:\Pycharm\ultralytics-main\wandb\run-20240515_165319-i3koqsy0\files\output.log
2024-05-15 16:53:34,825 DEBUG   HandlerThread:15772 [handler.py:handle_request():146] handle_request: status_report
2024-05-15 16:53:35,099 INFO    Thread-16 :15772 [dir_watcher.py:_on_file_modified():288] file/dir modified: D:\Pycharm\ultralytics-main\wandb\run-20240515_165319-i3koqsy0\files\output.log
2024-05-15 16:53:35,887 ERROR   wandb-upload_0:15772 [internal_api.py:upload_file():2557] upload_file exception https://storage.googleapis.com/wandb-production.appspot.com/666233/runs/i3koqsy0/wandb-metadata.json?Expires=1715849607&GoogleAccessId=gorilla-files-url-signer-man%40wandb-production.iam.gserviceaccount.com&Signature=I8ePYaZOwyI8zZPA4tahnlEYExo0t1IrHPFCVYc4uOqLrmyfPP0KB5TVuXw%2FPX3wl1HLBjSRfk8%2FMUUPbq18n3y2sXOJkLawRZgxKdaPHBiZQX4CwK0LLX0m4lZ1%2F85dvZaw%2F3uj2xpFkd1nUNNyc6XsGvdfWfiKM7oG3x1kvazsA7qQ5QUlKldrLMVPs4m2s95tKlR6u7rKV3H%2BWuvLnwVDwgiiT4QfdL3Dd5iQ%2BagRZl2Uuc6FnW3r04q5%2BOokVpJVqy9AkyKtN%2By%2FSuXGzL7pB9JKyEXTaCzP6clq06f9VIvLLCI%2FIZ9x79t%2Bt1EeVjTjuiYDg3UhLLGpRBPHlw%3D%3D: ('Connection aborted.', ConnectionResetError(10054, '远程主机强迫关闭了一个现有的连接。', None, 10054, None))
2024-05-15 16:53:35,889 ERROR   wandb-upload_0:15772 [internal_api.py:upload_file():2559] upload_file request headers: {'User-Agent': 'python-requests/2.28.2', 'Accept-Encoding': 'gzip, deflate', 'Accept': '*/*', 'Connection': 'keep-alive', 'Content-Length': '1195'}
2024-05-15 16:53:35,889 ERROR   wandb-upload_0:15772 [internal_api.py:upload_file():2561] upload_file response body: 
2024-05-15 16:53:37,110 INFO    Thread-16 :15772 [dir_watcher.py:_on_file_modified():288] file/dir modified: D:\Pycharm\ultralytics-main\wandb\run-20240515_165319-i3koqsy0\files\output.log
2024-05-15 16:53:39,117 INFO    Thread-16 :15772 [dir_watcher.py:_on_file_modified():288] file/dir modified: D:\Pycharm\ultralytics-main\wandb\run-20240515_165319-i3koqsy0\files\output.log
2024-05-15 16:53:39,971 DEBUG   HandlerThread:15772 [handler.py:handle_request():146] handle_request: status_report
2024-05-15 16:53:41,140 INFO    Thread-16 :15772 [dir_watcher.py:_on_file_modified():288] file/dir modified: D:\Pycharm\ultralytics-main\wandb\run-20240515_165319-i3koqsy0\files\output.log
2024-05-15 16:53:41,522 DEBUG   HandlerThread:15772 [handler.py:handle_request():146] handle_request: stop_status
2024-05-15 16:53:41,522 DEBUG   SenderThread:15772 [sender.py:send_request():407] send_request: stop_status
2024-05-15 16:53:41,524 DEBUG   HandlerThread:15772 [handler.py:handle_request():146] handle_request: internal_messages
2024-05-15 16:53:43,165 INFO    Thread-16 :15772 [dir_watcher.py:_on_file_modified():288] file/dir modified: D:\Pycharm\ultralytics-main\wandb\run-20240515_165319-i3koqsy0\files\output.log
2024-05-15 16:53:45,054 DEBUG   HandlerThread:15772 [handler.py:handle_request():146] handle_request: status_report
2024-05-15 16:53:45,186 INFO    Thread-16 :15772 [dir_watcher.py:_on_file_modified():288] file/dir modified: D:\Pycharm\ultralytics-main\wandb\run-20240515_165319-i3koqsy0\files\output.log
2024-05-15 16:53:45,600 ERROR   wandb-upload_0:15772 [internal_api.py:upload_file():2557] upload_file exception https://storage.googleapis.com/wandb-production.appspot.com/666233/runs/i3koqsy0/wandb-metadata.json?Expires=1715849607&GoogleAccessId=gorilla-files-url-signer-man%40wandb-production.iam.gserviceaccount.com&Signature=I8ePYaZOwyI8zZPA4tahnlEYExo0t1IrHPFCVYc4uOqLrmyfPP0KB5TVuXw%2FPX3wl1HLBjSRfk8%2FMUUPbq18n3y2sXOJkLawRZgxKdaPHBiZQX4CwK0LLX0m4lZ1%2F85dvZaw%2F3uj2xpFkd1nUNNyc6XsGvdfWfiKM7oG3x1kvazsA7qQ5QUlKldrLMVPs4m2s95tKlR6u7rKV3H%2BWuvLnwVDwgiiT4QfdL3Dd5iQ%2BagRZl2Uuc6FnW3r04q5%2BOokVpJVqy9AkyKtN%2By%2FSuXGzL7pB9JKyEXTaCzP6clq06f9VIvLLCI%2FIZ9x79t%2Bt1EeVjTjuiYDg3UhLLGpRBPHlw%3D%3D: ('Connection aborted.', ConnectionResetError(10054, '远程主机强迫关闭了一个现有的连接。', None, 10054, None))
2024-05-15 16:53:45,600 ERROR   wandb-upload_0:15772 [internal_api.py:upload_file():2559] upload_file request headers: {'User-Agent': 'python-requests/2.28.2', 'Accept-Encoding': 'gzip, deflate', 'Accept': '*/*', 'Connection': 'keep-alive', 'Content-Length': '1195'}
2024-05-15 16:53:45,600 ERROR   wandb-upload_0:15772 [internal_api.py:upload_file():2561] upload_file response body: 
2024-05-15 16:53:47,207 INFO    Thread-16 :15772 [dir_watcher.py:_on_file_modified():288] file/dir modified: D:\Pycharm\ultralytics-main\wandb\run-20240515_165319-i3koqsy0\files\output.log
