2024-05-20 14:27:59,983 INFO    StreamThr :30500 [internal.py:wandb_internal():86] W&B internal server running at pid: 30500, started at: 2024-05-20 14:27:59.982944
2024-05-20 14:27:59,984 DEBUG   HandlerThread:30500 [handler.py:handle_request():146] handle_request: status
2024-05-20 14:27:59,987 INFO    WriterThread:30500 [datastore.py:open_for_write():85] open: D:\Pycharm\ultralytics-main\wandb\run-20240520_142759-1icokd1d\run-1icokd1d.wandb
2024-05-20 14:27:59,988 DEBUG   SenderThread:30500 [sender.py:send():380] send: header
2024-05-20 14:27:59,989 DEBUG   SenderThread:30500 [sender.py:send():380] send: run
2024-05-20 14:28:00,840 INFO    SenderThread:30500 [dir_watcher.py:__init__():211] watching files in: D:\Pycharm\ultralytics-main\wandb\run-20240520_142759-1icokd1d\files
2024-05-20 14:28:00,841 INFO    SenderThread:30500 [sender.py:_start_run_threads():1124] run started: 1icokd1d with start time 1716186479.984938
2024-05-20 14:28:00,846 DEBUG   HandlerThread:30500 [handler.py:handle_request():146] handle_request: check_version
2024-05-20 14:28:00,846 DEBUG   SenderThread:30500 [sender.py:send_request():407] send_request: check_version
2024-05-20 14:28:01,342 DEBUG   HandlerThread:30500 [handler.py:handle_request():146] handle_request: run_start
2024-05-20 14:28:01,439 DEBUG   HandlerThread:30500 [system_info.py:__init__():32] System info init
2024-05-20 14:28:01,439 DEBUG   HandlerThread:30500 [system_info.py:__init__():47] System info init done
2024-05-20 14:28:01,439 INFO    HandlerThread:30500 [system_monitor.py:start():194] Starting system monitor
2024-05-20 14:28:01,439 INFO    SystemMonitor:30500 [system_monitor.py:_start():158] Starting system asset monitoring threads
2024-05-20 14:28:01,439 INFO    HandlerThread:30500 [system_monitor.py:probe():214] Collecting system info
2024-05-20 14:28:01,451 INFO    SystemMonitor:30500 [interfaces.py:start():190] Started cpu monitoring
2024-05-20 14:28:01,451 INFO    SystemMonitor:30500 [interfaces.py:start():190] Started disk monitoring
2024-05-20 14:28:01,452 INFO    SystemMonitor:30500 [interfaces.py:start():190] Started gpu monitoring
2024-05-20 14:28:01,463 INFO    SystemMonitor:30500 [interfaces.py:start():190] Started memory monitoring
2024-05-20 14:28:01,474 INFO    SystemMonitor:30500 [interfaces.py:start():190] Started network monitoring
2024-05-20 14:28:01,480 DEBUG   HandlerThread:30500 [system_info.py:probe():196] Probing system
2024-05-20 14:28:01,482 DEBUG   HandlerThread:30500 [gitlib.py:_init_repo():56] git repository is invalid
2024-05-20 14:28:01,482 DEBUG   HandlerThread:30500 [system_info.py:probe():244] Probing system done
2024-05-20 14:28:01,482 DEBUG   HandlerThread:30500 [system_monitor.py:probe():223] {'os': 'Windows-10-10.0.22631-SP0', 'python': '3.9.18', 'heartbeatAt': '2024-05-20T06:28:01.481669', 'startedAt': '2024-05-20T06:27:59.977962', 'docker': None, 'cuda': None, 'args': (), 'state': 'running', 'program': 'D:\\Pycharm\\ultralytics-main\\train.py', 'codePathLocal': 'train.py', 'codePath': 'train.py', 'host': 'DESKTOP-VH2CUSJ', 'username': 'DELL', 'executable': 'D:\\Anaconda\\envs\\DL\\python.exe', 'cpu_count': 10, 'cpu_count_logical': 16, 'cpu_freq': {'current': 2400.0, 'min': 0.0, 'max': 2400.0}, 'cpu_freq_per_core': [{'current': 2400.0, 'min': 0.0, 'max': 2400.0}], 'disk': {'/': {'total': 244.13964462280273, 'used': 188.03617095947266}}, 'gpu': 'NVIDIA GeForce RTX 4050 Laptop GPU', 'gpu_count': 1, 'gpu_devices': [{'name': 'NVIDIA GeForce RTX 4050 Laptop GPU', 'memory_total': 6439305216}], 'memory': {'total': 15.692092895507812}}
2024-05-20 14:28:01,482 INFO    HandlerThread:30500 [system_monitor.py:probe():224] Finished collecting system info
2024-05-20 14:28:01,482 INFO    HandlerThread:30500 [system_monitor.py:probe():227] Publishing system info
2024-05-20 14:28:01,482 DEBUG   HandlerThread:30500 [system_info.py:_save_pip():52] Saving list of pip packages installed into the current environment
2024-05-20 14:28:01,482 DEBUG   HandlerThread:30500 [system_info.py:_save_pip():68] Saving pip packages done
2024-05-20 14:28:01,482 DEBUG   HandlerThread:30500 [system_info.py:_save_conda():75] Saving list of conda packages installed into the current environment
2024-05-20 14:28:01,845 INFO    Thread-16 :30500 [dir_watcher.py:_on_file_created():271] file/dir created: D:\Pycharm\ultralytics-main\wandb\run-20240520_142759-1icokd1d\files\requirements.txt
2024-05-20 14:28:01,846 INFO    Thread-16 :30500 [dir_watcher.py:_on_file_created():271] file/dir created: D:\Pycharm\ultralytics-main\wandb\run-20240520_142759-1icokd1d\files\conda-environment.yaml
2024-05-20 14:28:07,484 DEBUG   HandlerThread:30500 [system_info.py:_save_conda():87] Saving conda packages done
2024-05-20 14:28:07,484 INFO    HandlerThread:30500 [system_monitor.py:probe():229] Finished publishing system info
2024-05-20 14:28:07,497 DEBUG   HandlerThread:30500 [handler.py:handle_request():146] handle_request: status_report
2024-05-20 14:28:07,497 DEBUG   HandlerThread:30500 [handler.py:handle_request():146] handle_request: keepalive
2024-05-20 14:28:07,498 DEBUG   SenderThread:30500 [sender.py:send():380] send: files
2024-05-20 14:28:07,498 INFO    SenderThread:30500 [sender.py:_save_file():1380] saving file wandb-metadata.json with policy now
2024-05-20 14:28:07,517 DEBUG   HandlerThread:30500 [handler.py:handle_request():146] handle_request: stop_status
2024-05-20 14:28:07,517 DEBUG   HandlerThread:30500 [handler.py:handle_request():146] handle_request: internal_messages
2024-05-20 14:28:07,517 DEBUG   SenderThread:30500 [sender.py:send_request():407] send_request: stop_status
2024-05-20 14:28:07,799 DEBUG   SenderThread:30500 [sender.py:send():380] send: telemetry
2024-05-20 14:28:07,882 INFO    Thread-16 :30500 [dir_watcher.py:_on_file_modified():288] file/dir modified: D:\Pycharm\ultralytics-main\wandb\run-20240520_142759-1icokd1d\files\conda-environment.yaml
2024-05-20 14:28:07,882 INFO    Thread-16 :30500 [dir_watcher.py:_on_file_created():271] file/dir created: D:\Pycharm\ultralytics-main\wandb\run-20240520_142759-1icokd1d\files\wandb-metadata.json
2024-05-20 14:28:07,883 INFO    Thread-16 :30500 [dir_watcher.py:_on_file_created():271] file/dir created: D:\Pycharm\ultralytics-main\wandb\run-20240520_142759-1icokd1d\files\output.log
2024-05-20 14:28:08,777 ERROR   wandb-upload_0:30500 [internal_api.py:upload_file():2557] upload_file exception https://storage.googleapis.com/wandb-production.appspot.com/666233/runs/1icokd1d/wandb-metadata.json?Expires=1716272888&GoogleAccessId=gorilla-files-url-signer-man%40wandb-production.iam.gserviceaccount.com&Signature=KRaje6OZpHtwsgriq5VISBISFU56O8CBW1UYgvhAfnK%2BnZAeZsB%2FzgfL7fOmbMSg1%2BVQPb3TLRJCv1QoGwsOKZpvt4hr1N2C%2B77PXTsCLvOaqOl20dJPnXgkeDTLyE1iG2fGuYqgWq0DVP9f99W2i07qGcrO8m0jWrjj4EZ%2FhQU9Lw6yXdRFjkSyKns%2BghL0%2FWL1xz0TEssKLZxPIaHYOoYYVF1e%2B%2BPd0VyRmmar98zKxkYT58PA5OSmZJxfARfh6V%2BUwo8aFpZIOpgh293%2Borg%2BXqzushM7M4%2BHI6G3NMmOlWEslo8uxSFVOCEGhcG1Px44t7GTt8rghZfkGyp2dg%3D%3D: ('Connection aborted.', ConnectionResetError(10054, '远程主机强迫关闭了一个现有的连接。', None, 10054, None))
2024-05-20 14:28:08,777 ERROR   wandb-upload_0:30500 [internal_api.py:upload_file():2559] upload_file request headers: {'User-Agent': 'python-requests/2.28.2', 'Accept-Encoding': 'gzip, deflate', 'Accept': '*/*', 'Connection': 'keep-alive', 'Content-Length': '1195'}
2024-05-20 14:28:08,777 ERROR   wandb-upload_0:30500 [internal_api.py:upload_file():2561] upload_file response body: 
2024-05-20 14:28:09,943 INFO    Thread-16 :30500 [dir_watcher.py:_on_file_modified():288] file/dir modified: D:\Pycharm\ultralytics-main\wandb\run-20240520_142759-1icokd1d\files\output.log
2024-05-20 14:28:10,494 ERROR   wandb-upload_0:30500 [internal_api.py:upload_file():2557] upload_file exception https://storage.googleapis.com/wandb-production.appspot.com/666233/runs/1icokd1d/wandb-metadata.json?Expires=1716272888&GoogleAccessId=gorilla-files-url-signer-man%40wandb-production.iam.gserviceaccount.com&Signature=KRaje6OZpHtwsgriq5VISBISFU56O8CBW1UYgvhAfnK%2BnZAeZsB%2FzgfL7fOmbMSg1%2BVQPb3TLRJCv1QoGwsOKZpvt4hr1N2C%2B77PXTsCLvOaqOl20dJPnXgkeDTLyE1iG2fGuYqgWq0DVP9f99W2i07qGcrO8m0jWrjj4EZ%2FhQU9Lw6yXdRFjkSyKns%2BghL0%2FWL1xz0TEssKLZxPIaHYOoYYVF1e%2B%2BPd0VyRmmar98zKxkYT58PA5OSmZJxfARfh6V%2BUwo8aFpZIOpgh293%2Borg%2BXqzushM7M4%2BHI6G3NMmOlWEslo8uxSFVOCEGhcG1Px44t7GTt8rghZfkGyp2dg%3D%3D: ('Connection aborted.', ConnectionResetError(10054, '远程主机强迫关闭了一个现有的连接。', None, 10054, None))
2024-05-20 14:28:10,494 ERROR   wandb-upload_0:30500 [internal_api.py:upload_file():2559] upload_file request headers: {'User-Agent': 'python-requests/2.28.2', 'Accept-Encoding': 'gzip, deflate', 'Accept': '*/*', 'Connection': 'keep-alive', 'Content-Length': '1195'}
2024-05-20 14:28:10,494 ERROR   wandb-upload_0:30500 [internal_api.py:upload_file():2561] upload_file response body: 
2024-05-20 14:28:10,942 DEBUG   HandlerThread:30500 [handler.py:handle_request():146] handle_request: status_report
2024-05-20 14:28:13,504 ERROR   wandb-upload_0:30500 [internal_api.py:upload_file():2557] upload_file exception https://storage.googleapis.com/wandb-production.appspot.com/666233/runs/1icokd1d/wandb-metadata.json?Expires=1716272888&GoogleAccessId=gorilla-files-url-signer-man%40wandb-production.iam.gserviceaccount.com&Signature=KRaje6OZpHtwsgriq5VISBISFU56O8CBW1UYgvhAfnK%2BnZAeZsB%2FzgfL7fOmbMSg1%2BVQPb3TLRJCv1QoGwsOKZpvt4hr1N2C%2B77PXTsCLvOaqOl20dJPnXgkeDTLyE1iG2fGuYqgWq0DVP9f99W2i07qGcrO8m0jWrjj4EZ%2FhQU9Lw6yXdRFjkSyKns%2BghL0%2FWL1xz0TEssKLZxPIaHYOoYYVF1e%2B%2BPd0VyRmmar98zKxkYT58PA5OSmZJxfARfh6V%2BUwo8aFpZIOpgh293%2Borg%2BXqzushM7M4%2BHI6G3NMmOlWEslo8uxSFVOCEGhcG1Px44t7GTt8rghZfkGyp2dg%3D%3D: ('Connection aborted.', ConnectionResetError(10054, '远程主机强迫关闭了一个现有的连接。', None, 10054, None))
2024-05-20 14:28:13,504 ERROR   wandb-upload_0:30500 [internal_api.py:upload_file():2559] upload_file request headers: {'User-Agent': 'python-requests/2.28.2', 'Accept-Encoding': 'gzip, deflate', 'Accept': '*/*', 'Connection': 'keep-alive', 'Content-Length': '1195'}
2024-05-20 14:28:13,504 ERROR   wandb-upload_0:30500 [internal_api.py:upload_file():2561] upload_file response body: 
2024-05-20 14:28:13,504 INFO    wandb-upload_0:30500 [retry.py:__call__():172] Retry attempt failed:
Traceback (most recent call last):
  File "D:\Anaconda\envs\DL\lib\site-packages\urllib3\connectionpool.py", line 715, in urlopen
    httplib_response = self._make_request(
  File "D:\Anaconda\envs\DL\lib\site-packages\urllib3\connectionpool.py", line 404, in _make_request
    self._validate_conn(conn)
  File "D:\Anaconda\envs\DL\lib\site-packages\urllib3\connectionpool.py", line 1058, in _validate_conn
    conn.connect()
  File "D:\Anaconda\envs\DL\lib\site-packages\urllib3\connection.py", line 419, in connect
    self.sock = ssl_wrap_socket(
  File "D:\Anaconda\envs\DL\lib\site-packages\urllib3\util\ssl_.py", line 449, in ssl_wrap_socket
    ssl_sock = _ssl_wrap_socket_impl(
  File "D:\Anaconda\envs\DL\lib\site-packages\urllib3\util\ssl_.py", line 493, in _ssl_wrap_socket_impl
    return ssl_context.wrap_socket(sock, server_hostname=server_hostname)
  File "D:\Anaconda\envs\DL\lib\ssl.py", line 501, in wrap_socket
    return self.sslsocket_class._create(
  File "D:\Anaconda\envs\DL\lib\ssl.py", line 1074, in _create
    self.do_handshake()
  File "D:\Anaconda\envs\DL\lib\ssl.py", line 1343, in do_handshake
    self._sslobj.do_handshake()
ConnectionResetError: [WinError 10054] 远程主机强迫关闭了一个现有的连接。

During handling of the above exception, another exception occurred:

Traceback (most recent call last):
  File "D:\Anaconda\envs\DL\lib\site-packages\requests\adapters.py", line 489, in send
    resp = conn.urlopen(
  File "D:\Anaconda\envs\DL\lib\site-packages\urllib3\connectionpool.py", line 799, in urlopen
    retries = retries.increment(
  File "D:\Anaconda\envs\DL\lib\site-packages\urllib3\util\retry.py", line 550, in increment
    raise six.reraise(type(error), error, _stacktrace)
  File "D:\Anaconda\envs\DL\lib\site-packages\urllib3\packages\six.py", line 769, in reraise
    raise value.with_traceback(tb)
  File "D:\Anaconda\envs\DL\lib\site-packages\urllib3\connectionpool.py", line 715, in urlopen
    httplib_response = self._make_request(
  File "D:\Anaconda\envs\DL\lib\site-packages\urllib3\connectionpool.py", line 404, in _make_request
    self._validate_conn(conn)
  File "D:\Anaconda\envs\DL\lib\site-packages\urllib3\connectionpool.py", line 1058, in _validate_conn
    conn.connect()
  File "D:\Anaconda\envs\DL\lib\site-packages\urllib3\connection.py", line 419, in connect
    self.sock = ssl_wrap_socket(
  File "D:\Anaconda\envs\DL\lib\site-packages\urllib3\util\ssl_.py", line 449, in ssl_wrap_socket
    ssl_sock = _ssl_wrap_socket_impl(
  File "D:\Anaconda\envs\DL\lib\site-packages\urllib3\util\ssl_.py", line 493, in _ssl_wrap_socket_impl
    return ssl_context.wrap_socket(sock, server_hostname=server_hostname)
  File "D:\Anaconda\envs\DL\lib\ssl.py", line 501, in wrap_socket
    return self.sslsocket_class._create(
  File "D:\Anaconda\envs\DL\lib\ssl.py", line 1074, in _create
    self.do_handshake()
  File "D:\Anaconda\envs\DL\lib\ssl.py", line 1343, in do_handshake
    self._sslobj.do_handshake()
urllib3.exceptions.ProtocolError: ('Connection aborted.', ConnectionResetError(10054, '远程主机强迫关闭了一个现有的连接。', None, 10054, None))

During handling of the above exception, another exception occurred:

Traceback (most recent call last):
  File "D:\Anaconda\envs\DL\lib\site-packages\wandb\sdk\internal\internal_api.py", line 2550, in upload_file
    response = self._upload_file_session.put(
  File "D:\Anaconda\envs\DL\lib\site-packages\requests\sessions.py", line 647, in put
    return self.request("PUT", url, data=data, **kwargs)
  File "D:\Anaconda\envs\DL\lib\site-packages\requests\sessions.py", line 587, in request
    resp = self.send(prep, **send_kwargs)
  File "D:\Anaconda\envs\DL\lib\site-packages\requests\sessions.py", line 701, in send
    r = adapter.send(request, **kwargs)
  File "D:\Anaconda\envs\DL\lib\site-packages\requests\adapters.py", line 547, in send
    raise ConnectionError(err, request=request)
requests.exceptions.ConnectionError: ('Connection aborted.', ConnectionResetError(10054, '远程主机强迫关闭了一个现有的连接。', None, 10054, None))

During handling of the above exception, another exception occurred:

Traceback (most recent call last):
  File "D:\Anaconda\envs\DL\lib\site-packages\wandb\sdk\lib\retry.py", line 131, in __call__
    result = self._call_fn(*args, **kwargs)
  File "D:\Anaconda\envs\DL\lib\site-packages\wandb\sdk\internal\internal_api.py", line 2581, in upload_file
    raise _e.with_traceback(sys.exc_info()[2])
  File "D:\Anaconda\envs\DL\lib\site-packages\wandb\sdk\internal\internal_api.py", line 2550, in upload_file
    response = self._upload_file_session.put(
  File "D:\Anaconda\envs\DL\lib\site-packages\requests\sessions.py", line 647, in put
    return self.request("PUT", url, data=data, **kwargs)
  File "D:\Anaconda\envs\DL\lib\site-packages\requests\sessions.py", line 587, in request
    resp = self.send(prep, **send_kwargs)
  File "D:\Anaconda\envs\DL\lib\site-packages\requests\sessions.py", line 701, in send
    r = adapter.send(request, **kwargs)
  File "D:\Anaconda\envs\DL\lib\site-packages\requests\adapters.py", line 547, in send
    raise ConnectionError(err, request=request)
wandb.sdk.lib.retry.TransientError: None
2024-05-20 14:28:16,155 DEBUG   HandlerThread:30500 [handler.py:handle_request():146] handle_request: status_report
2024-05-20 14:28:17,936 ERROR   wandb-upload_0:30500 [internal_api.py:upload_file():2557] upload_file exception https://storage.googleapis.com/wandb-production.appspot.com/666233/runs/1icokd1d/wandb-metadata.json?Expires=1716272888&GoogleAccessId=gorilla-files-url-signer-man%40wandb-production.iam.gserviceaccount.com&Signature=KRaje6OZpHtwsgriq5VISBISFU56O8CBW1UYgvhAfnK%2BnZAeZsB%2FzgfL7fOmbMSg1%2BVQPb3TLRJCv1QoGwsOKZpvt4hr1N2C%2B77PXTsCLvOaqOl20dJPnXgkeDTLyE1iG2fGuYqgWq0DVP9f99W2i07qGcrO8m0jWrjj4EZ%2FhQU9Lw6yXdRFjkSyKns%2BghL0%2FWL1xz0TEssKLZxPIaHYOoYYVF1e%2B%2BPd0VyRmmar98zKxkYT58PA5OSmZJxfARfh6V%2BUwo8aFpZIOpgh293%2Borg%2BXqzushM7M4%2BHI6G3NMmOlWEslo8uxSFVOCEGhcG1Px44t7GTt8rghZfkGyp2dg%3D%3D: ('Connection aborted.', ConnectionResetError(10054, '远程主机强迫关闭了一个现有的连接。', None, 10054, None))
2024-05-20 14:28:17,936 ERROR   wandb-upload_0:30500 [internal_api.py:upload_file():2559] upload_file request headers: {'User-Agent': 'python-requests/2.28.2', 'Accept-Encoding': 'gzip, deflate', 'Accept': '*/*', 'Connection': 'keep-alive', 'Content-Length': '1195'}
2024-05-20 14:28:17,936 ERROR   wandb-upload_0:30500 [internal_api.py:upload_file():2561] upload_file response body: 
2024-05-20 14:28:18,165 INFO    Thread-16 :30500 [dir_watcher.py:_on_file_modified():288] file/dir modified: D:\Pycharm\ultralytics-main\wandb\run-20240520_142759-1icokd1d\files\output.log
2024-05-20 14:28:20,187 INFO    Thread-16 :30500 [dir_watcher.py:_on_file_modified():288] file/dir modified: D:\Pycharm\ultralytics-main\wandb\run-20240520_142759-1icokd1d\files\output.log
2024-05-20 14:28:21,772 DEBUG   HandlerThread:30500 [handler.py:handle_request():146] handle_request: status_report
2024-05-20 14:28:22,507 DEBUG   HandlerThread:30500 [handler.py:handle_request():146] handle_request: internal_messages
2024-05-20 14:28:22,519 DEBUG   HandlerThread:30500 [handler.py:handle_request():146] handle_request: stop_status
2024-05-20 14:28:22,520 DEBUG   SenderThread:30500 [sender.py:send_request():407] send_request: stop_status
2024-05-20 14:28:24,222 INFO    Thread-16 :30500 [dir_watcher.py:_on_file_modified():288] file/dir modified: D:\Pycharm\ultralytics-main\wandb\run-20240520_142759-1icokd1d\files\output.log
2024-05-20 14:28:26,237 INFO    Thread-16 :30500 [dir_watcher.py:_on_file_modified():288] file/dir modified: D:\Pycharm\ultralytics-main\wandb\run-20240520_142759-1icokd1d\files\output.log
2024-05-20 14:28:26,821 DEBUG   HandlerThread:30500 [handler.py:handle_request():146] handle_request: status_report
2024-05-20 14:28:27,996 ERROR   wandb-upload_0:30500 [internal_api.py:upload_file():2557] upload_file exception https://storage.googleapis.com/wandb-production.appspot.com/666233/runs/1icokd1d/wandb-metadata.json?Expires=1716272888&GoogleAccessId=gorilla-files-url-signer-man%40wandb-production.iam.gserviceaccount.com&Signature=KRaje6OZpHtwsgriq5VISBISFU56O8CBW1UYgvhAfnK%2BnZAeZsB%2FzgfL7fOmbMSg1%2BVQPb3TLRJCv1QoGwsOKZpvt4hr1N2C%2B77PXTsCLvOaqOl20dJPnXgkeDTLyE1iG2fGuYqgWq0DVP9f99W2i07qGcrO8m0jWrjj4EZ%2FhQU9Lw6yXdRFjkSyKns%2BghL0%2FWL1xz0TEssKLZxPIaHYOoYYVF1e%2B%2BPd0VyRmmar98zKxkYT58PA5OSmZJxfARfh6V%2BUwo8aFpZIOpgh293%2Borg%2BXqzushM7M4%2BHI6G3NMmOlWEslo8uxSFVOCEGhcG1Px44t7GTt8rghZfkGyp2dg%3D%3D: ('Connection aborted.', ConnectionResetError(10054, '远程主机强迫关闭了一个现有的连接。', None, 10054, None))
2024-05-20 14:28:27,996 ERROR   wandb-upload_0:30500 [internal_api.py:upload_file():2559] upload_file request headers: {'User-Agent': 'python-requests/2.28.2', 'Accept-Encoding': 'gzip, deflate', 'Accept': '*/*', 'Connection': 'keep-alive', 'Content-Length': '1195'}
2024-05-20 14:28:27,996 ERROR   wandb-upload_0:30500 [internal_api.py:upload_file():2561] upload_file response body: 
2024-05-20 14:28:28,254 INFO    Thread-16 :30500 [dir_watcher.py:_on_file_modified():288] file/dir modified: D:\Pycharm\ultralytics-main\wandb\run-20240520_142759-1icokd1d\files\output.log
2024-05-20 14:28:30,280 INFO    Thread-16 :30500 [dir_watcher.py:_on_file_modified():288] file/dir modified: D:\Pycharm\ultralytics-main\wandb\run-20240520_142759-1icokd1d\files\output.log
2024-05-20 14:28:31,928 DEBUG   HandlerThread:30500 [handler.py:handle_request():146] handle_request: status_report
2024-05-20 14:28:32,304 INFO    Thread-16 :30500 [dir_watcher.py:_on_file_modified():288] file/dir modified: D:\Pycharm\ultralytics-main\wandb\run-20240520_142759-1icokd1d\files\config.yaml
2024-05-20 14:28:32,305 INFO    Thread-16 :30500 [dir_watcher.py:_on_file_modified():288] file/dir modified: D:\Pycharm\ultralytics-main\wandb\run-20240520_142759-1icokd1d\files\output.log
