2024-05-17 11:39:42,018 INFO    StreamThr :32304 [internal.py:wandb_internal():86] W&B internal server running at pid: 32304, started at: 2024-05-17 11:39:42.018534
2024-05-17 11:39:42,018 DEBUG   HandlerThread:32304 [handler.py:handle_request():146] handle_request: status
2024-05-17 11:39:42,026 INFO    WriterThread:32304 [datastore.py:open_for_write():85] open: D:\Pycharm\ultralytics-main\wandb\run-20240517_113942-hdn8hdwc\run-hdn8hdwc.wandb
2024-05-17 11:39:42,026 DEBUG   SenderThread:32304 [sender.py:send():380] send: header
2024-05-17 11:39:42,026 DEBUG   SenderThread:32304 [sender.py:send():380] send: run
2024-05-17 11:39:42,830 INFO    SenderThread:32304 [dir_watcher.py:__init__():211] watching files in: D:\Pycharm\ultralytics-main\wandb\run-20240517_113942-hdn8hdwc\files
2024-05-17 11:39:42,830 INFO    SenderThread:32304 [sender.py:_start_run_threads():1124] run started: hdn8hdwc with start time 1715917182.018534
2024-05-17 11:39:42,834 DEBUG   HandlerThread:32304 [handler.py:handle_request():146] handle_request: check_version
2024-05-17 11:39:42,834 DEBUG   SenderThread:32304 [sender.py:send_request():407] send_request: check_version
2024-05-17 11:39:43,221 DEBUG   HandlerThread:32304 [handler.py:handle_request():146] handle_request: run_start
2024-05-17 11:39:43,249 DEBUG   HandlerThread:32304 [system_info.py:__init__():32] System info init
2024-05-17 11:39:43,249 DEBUG   HandlerThread:32304 [system_info.py:__init__():47] System info init done
2024-05-17 11:39:43,249 INFO    HandlerThread:32304 [system_monitor.py:start():194] Starting system monitor
2024-05-17 11:39:43,249 INFO    SystemMonitor:32304 [system_monitor.py:_start():158] Starting system asset monitoring threads
2024-05-17 11:39:43,249 INFO    HandlerThread:32304 [system_monitor.py:probe():214] Collecting system info
2024-05-17 11:39:43,253 INFO    SystemMonitor:32304 [interfaces.py:start():190] Started cpu monitoring
2024-05-17 11:39:43,257 INFO    SystemMonitor:32304 [interfaces.py:start():190] Started disk monitoring
2024-05-17 11:39:43,257 INFO    SystemMonitor:32304 [interfaces.py:start():190] Started gpu monitoring
2024-05-17 11:39:43,261 INFO    SystemMonitor:32304 [interfaces.py:start():190] Started memory monitoring
2024-05-17 11:39:43,269 INFO    SystemMonitor:32304 [interfaces.py:start():190] Started network monitoring
2024-05-17 11:39:43,273 DEBUG   HandlerThread:32304 [system_info.py:probe():196] Probing system
2024-05-17 11:39:43,277 DEBUG   HandlerThread:32304 [gitlib.py:_init_repo():56] git repository is invalid
2024-05-17 11:39:43,277 DEBUG   HandlerThread:32304 [system_info.py:probe():244] Probing system done
2024-05-17 11:39:43,277 DEBUG   HandlerThread:32304 [system_monitor.py:probe():223] {'os': 'Windows-10-10.0.22631-SP0', 'python': '3.9.18', 'heartbeatAt': '2024-05-17T03:39:43.273710', 'startedAt': '2024-05-17T03:39:42.010540', 'docker': None, 'cuda': None, 'args': (), 'state': 'running', 'program': 'D:\\Pycharm\\ultralytics-main\\train.py', 'codePathLocal': 'train.py', 'codePath': 'train.py', 'host': 'DESKTOP-VH2CUSJ', 'username': 'DELL', 'executable': 'D:\\Anaconda\\envs\\DL\\python.exe', 'cpu_count': 10, 'cpu_count_logical': 16, 'cpu_freq': {'current': 2400.0, 'min': 0.0, 'max': 2400.0}, 'cpu_freq_per_core': [{'current': 2400.0, 'min': 0.0, 'max': 2400.0}], 'disk': {'/': {'total': 244.13964462280273, 'used': 176.70327377319336}}, 'gpu': 'NVIDIA GeForce RTX 4050 Laptop GPU', 'gpu_count': 1, 'gpu_devices': [{'name': 'NVIDIA GeForce RTX 4050 Laptop GPU', 'memory_total': 6439305216}], 'memory': {'total': 15.692092895507812}}
2024-05-17 11:39:43,277 INFO    HandlerThread:32304 [system_monitor.py:probe():224] Finished collecting system info
2024-05-17 11:39:43,277 INFO    HandlerThread:32304 [system_monitor.py:probe():227] Publishing system info
2024-05-17 11:39:43,277 DEBUG   HandlerThread:32304 [system_info.py:_save_pip():52] Saving list of pip packages installed into the current environment
2024-05-17 11:39:43,277 DEBUG   HandlerThread:32304 [system_info.py:_save_pip():68] Saving pip packages done
2024-05-17 11:39:43,277 DEBUG   HandlerThread:32304 [system_info.py:_save_conda():75] Saving list of conda packages installed into the current environment
2024-05-17 11:39:43,837 INFO    Thread-16 :32304 [dir_watcher.py:_on_file_created():271] file/dir created: D:\Pycharm\ultralytics-main\wandb\run-20240517_113942-hdn8hdwc\files\requirements.txt
2024-05-17 11:39:43,837 INFO    Thread-16 :32304 [dir_watcher.py:_on_file_created():271] file/dir created: D:\Pycharm\ultralytics-main\wandb\run-20240517_113942-hdn8hdwc\files\conda-environment.yaml
2024-05-17 11:39:51,792 DEBUG   HandlerThread:32304 [system_info.py:_save_conda():87] Saving conda packages done
2024-05-17 11:39:51,795 INFO    HandlerThread:32304 [system_monitor.py:probe():229] Finished publishing system info
2024-05-17 11:39:51,800 DEBUG   HandlerThread:32304 [handler.py:handle_request():146] handle_request: status_report
2024-05-17 11:39:51,804 DEBUG   HandlerThread:32304 [handler.py:handle_request():146] handle_request: keepalive
2024-05-17 11:39:51,804 DEBUG   SenderThread:32304 [sender.py:send():380] send: files
2024-05-17 11:39:51,804 INFO    SenderThread:32304 [sender.py:_save_file():1380] saving file wandb-metadata.json with policy now
2024-05-17 11:39:51,808 DEBUG   HandlerThread:32304 [handler.py:handle_request():146] handle_request: stop_status
2024-05-17 11:39:51,808 DEBUG   SenderThread:32304 [sender.py:send_request():407] send_request: stop_status
2024-05-17 11:39:51,808 DEBUG   HandlerThread:32304 [handler.py:handle_request():146] handle_request: internal_messages
2024-05-17 11:39:51,912 INFO    Thread-16 :32304 [dir_watcher.py:_on_file_modified():288] file/dir modified: D:\Pycharm\ultralytics-main\wandb\run-20240517_113942-hdn8hdwc\files\conda-environment.yaml
2024-05-17 11:39:51,912 INFO    Thread-16 :32304 [dir_watcher.py:_on_file_created():271] file/dir created: D:\Pycharm\ultralytics-main\wandb\run-20240517_113942-hdn8hdwc\files\wandb-metadata.json
2024-05-17 11:39:52,132 DEBUG   SenderThread:32304 [sender.py:send():380] send: telemetry
2024-05-17 11:39:52,887 ERROR   wandb-upload_0:32304 [internal_api.py:upload_file():2557] upload_file exception https://storage.googleapis.com/wandb-production.appspot.com/666233/runs/hdn8hdwc/wandb-metadata.json?Expires=1716003592&GoogleAccessId=gorilla-files-url-signer-man%40wandb-production.iam.gserviceaccount.com&Signature=LpwFdENp4zmX4uWoq0uykAxdGsEbHuep5mjx%2FN71x3YiFjNukKLH9Z%2FdnEU2SCYS8AGhOO5%2FbgJcxYA1yQSN%2FF6PF%2FdwZP7cp4rcbVccXIp7C8LH%2FkbqMCu%2FNLnkrObv1EJEwHQH%2BBsorOmIU0A9Z0zP7PFnn24W9JOHuwGF9OvjflLJuOylqPHWNtk1DqOPJecyxenhgFvVQBH6C4wwV2se6MS%2BGssvYyHr7d0Kom2oLyNHWsDXftPD0qhsII9xa9zHyaDwp44ZsepcnzbesAzliuV5tPgFnlkI7wsM%2BND2ErGKHHDQOs9DCyFJoXy52C7Gk9CmD8ZzmR0nlJRn6w%3D%3D: ('Connection aborted.', ConnectionResetError(10054, '远程主机强迫关闭了一个现有的连接。', None, 10054, None))
2024-05-17 11:39:52,887 ERROR   wandb-upload_0:32304 [internal_api.py:upload_file():2559] upload_file request headers: {'User-Agent': 'python-requests/2.28.2', 'Accept-Encoding': 'gzip, deflate', 'Accept': '*/*', 'Connection': 'keep-alive', 'Content-Length': '1195'}
2024-05-17 11:39:52,887 ERROR   wandb-upload_0:32304 [internal_api.py:upload_file():2561] upload_file response body: 
2024-05-17 11:39:52,915 INFO    Thread-16 :32304 [dir_watcher.py:_on_file_created():271] file/dir created: D:\Pycharm\ultralytics-main\wandb\run-20240517_113942-hdn8hdwc\files\output.log
2024-05-17 11:39:53,143 DEBUG   HandlerThread:32304 [handler.py:handle_request():146] handle_request: status_report
2024-05-17 11:39:54,430 ERROR   wandb-upload_0:32304 [internal_api.py:upload_file():2557] upload_file exception https://storage.googleapis.com/wandb-production.appspot.com/666233/runs/hdn8hdwc/wandb-metadata.json?Expires=1716003592&GoogleAccessId=gorilla-files-url-signer-man%40wandb-production.iam.gserviceaccount.com&Signature=LpwFdENp4zmX4uWoq0uykAxdGsEbHuep5mjx%2FN71x3YiFjNukKLH9Z%2FdnEU2SCYS8AGhOO5%2FbgJcxYA1yQSN%2FF6PF%2FdwZP7cp4rcbVccXIp7C8LH%2FkbqMCu%2FNLnkrObv1EJEwHQH%2BBsorOmIU0A9Z0zP7PFnn24W9JOHuwGF9OvjflLJuOylqPHWNtk1DqOPJecyxenhgFvVQBH6C4wwV2se6MS%2BGssvYyHr7d0Kom2oLyNHWsDXftPD0qhsII9xa9zHyaDwp44ZsepcnzbesAzliuV5tPgFnlkI7wsM%2BND2ErGKHHDQOs9DCyFJoXy52C7Gk9CmD8ZzmR0nlJRn6w%3D%3D: ('Connection aborted.', ConnectionResetError(10054, '远程主机强迫关闭了一个现有的连接。', None, 10054, None))
2024-05-17 11:39:54,430 ERROR   wandb-upload_0:32304 [internal_api.py:upload_file():2559] upload_file request headers: {'User-Agent': 'python-requests/2.28.2', 'Accept-Encoding': 'gzip, deflate', 'Accept': '*/*', 'Connection': 'keep-alive', 'Content-Length': '1195'}
2024-05-17 11:39:54,430 ERROR   wandb-upload_0:32304 [internal_api.py:upload_file():2561] upload_file response body: 
2024-05-17 11:39:54,935 INFO    Thread-16 :32304 [dir_watcher.py:_on_file_modified():288] file/dir modified: D:\Pycharm\ultralytics-main\wandb\run-20240517_113942-hdn8hdwc\files\output.log
2024-05-17 11:39:57,321 ERROR   wandb-upload_0:32304 [internal_api.py:upload_file():2557] upload_file exception https://storage.googleapis.com/wandb-production.appspot.com/666233/runs/hdn8hdwc/wandb-metadata.json?Expires=1716003592&GoogleAccessId=gorilla-files-url-signer-man%40wandb-production.iam.gserviceaccount.com&Signature=LpwFdENp4zmX4uWoq0uykAxdGsEbHuep5mjx%2FN71x3YiFjNukKLH9Z%2FdnEU2SCYS8AGhOO5%2FbgJcxYA1yQSN%2FF6PF%2FdwZP7cp4rcbVccXIp7C8LH%2FkbqMCu%2FNLnkrObv1EJEwHQH%2BBsorOmIU0A9Z0zP7PFnn24W9JOHuwGF9OvjflLJuOylqPHWNtk1DqOPJecyxenhgFvVQBH6C4wwV2se6MS%2BGssvYyHr7d0Kom2oLyNHWsDXftPD0qhsII9xa9zHyaDwp44ZsepcnzbesAzliuV5tPgFnlkI7wsM%2BND2ErGKHHDQOs9DCyFJoXy52C7Gk9CmD8ZzmR0nlJRn6w%3D%3D: ('Connection aborted.', ConnectionResetError(10054, '远程主机强迫关闭了一个现有的连接。', None, 10054, None))
2024-05-17 11:39:57,321 ERROR   wandb-upload_0:32304 [internal_api.py:upload_file():2559] upload_file request headers: {'User-Agent': 'python-requests/2.28.2', 'Accept-Encoding': 'gzip, deflate', 'Accept': '*/*', 'Connection': 'keep-alive', 'Content-Length': '1195'}
2024-05-17 11:39:57,321 ERROR   wandb-upload_0:32304 [internal_api.py:upload_file():2561] upload_file response body: 
2024-05-17 11:39:57,321 INFO    wandb-upload_0:32304 [retry.py:__call__():172] Retry attempt failed:
Traceback (most recent call last):
  File "D:\Anaconda\envs\DL\lib\site-packages\urllib3\connectionpool.py", line 715, in urlopen
    httplib_response = self._make_request(
  File "D:\Anaconda\envs\DL\lib\site-packages\urllib3\connectionpool.py", line 404, in _make_request
    self._validate_conn(conn)
  File "D:\Anaconda\envs\DL\lib\site-packages\urllib3\connectionpool.py", line 1058, in _validate_conn
    conn.connect()
  File "D:\Anaconda\envs\DL\lib\site-packages\urllib3\connection.py", line 419, in connect
    self.sock = ssl_wrap_socket(
  File "D:\Anaconda\envs\DL\lib\site-packages\urllib3\util\ssl_.py", line 449, in ssl_wrap_socket
    ssl_sock = _ssl_wrap_socket_impl(
  File "D:\Anaconda\envs\DL\lib\site-packages\urllib3\util\ssl_.py", line 493, in _ssl_wrap_socket_impl
    return ssl_context.wrap_socket(sock, server_hostname=server_hostname)
  File "D:\Anaconda\envs\DL\lib\ssl.py", line 501, in wrap_socket
    return self.sslsocket_class._create(
  File "D:\Anaconda\envs\DL\lib\ssl.py", line 1074, in _create
    self.do_handshake()
  File "D:\Anaconda\envs\DL\lib\ssl.py", line 1343, in do_handshake
    self._sslobj.do_handshake()
ConnectionResetError: [WinError 10054] 远程主机强迫关闭了一个现有的连接。

During handling of the above exception, another exception occurred:

Traceback (most recent call last):
  File "D:\Anaconda\envs\DL\lib\site-packages\requests\adapters.py", line 489, in send
    resp = conn.urlopen(
  File "D:\Anaconda\envs\DL\lib\site-packages\urllib3\connectionpool.py", line 799, in urlopen
    retries = retries.increment(
  File "D:\Anaconda\envs\DL\lib\site-packages\urllib3\util\retry.py", line 550, in increment
    raise six.reraise(type(error), error, _stacktrace)
  File "D:\Anaconda\envs\DL\lib\site-packages\urllib3\packages\six.py", line 769, in reraise
    raise value.with_traceback(tb)
  File "D:\Anaconda\envs\DL\lib\site-packages\urllib3\connectionpool.py", line 715, in urlopen
    httplib_response = self._make_request(
  File "D:\Anaconda\envs\DL\lib\site-packages\urllib3\connectionpool.py", line 404, in _make_request
    self._validate_conn(conn)
  File "D:\Anaconda\envs\DL\lib\site-packages\urllib3\connectionpool.py", line 1058, in _validate_conn
    conn.connect()
  File "D:\Anaconda\envs\DL\lib\site-packages\urllib3\connection.py", line 419, in connect
    self.sock = ssl_wrap_socket(
  File "D:\Anaconda\envs\DL\lib\site-packages\urllib3\util\ssl_.py", line 449, in ssl_wrap_socket
    ssl_sock = _ssl_wrap_socket_impl(
  File "D:\Anaconda\envs\DL\lib\site-packages\urllib3\util\ssl_.py", line 493, in _ssl_wrap_socket_impl
    return ssl_context.wrap_socket(sock, server_hostname=server_hostname)
  File "D:\Anaconda\envs\DL\lib\ssl.py", line 501, in wrap_socket
    return self.sslsocket_class._create(
  File "D:\Anaconda\envs\DL\lib\ssl.py", line 1074, in _create
    self.do_handshake()
  File "D:\Anaconda\envs\DL\lib\ssl.py", line 1343, in do_handshake
    self._sslobj.do_handshake()
urllib3.exceptions.ProtocolError: ('Connection aborted.', ConnectionResetError(10054, '远程主机强迫关闭了一个现有的连接。', None, 10054, None))

During handling of the above exception, another exception occurred:

Traceback (most recent call last):
  File "D:\Anaconda\envs\DL\lib\site-packages\wandb\sdk\internal\internal_api.py", line 2550, in upload_file
    response = self._upload_file_session.put(
  File "D:\Anaconda\envs\DL\lib\site-packages\requests\sessions.py", line 647, in put
    return self.request("PUT", url, data=data, **kwargs)
  File "D:\Anaconda\envs\DL\lib\site-packages\requests\sessions.py", line 587, in request
    resp = self.send(prep, **send_kwargs)
  File "D:\Anaconda\envs\DL\lib\site-packages\requests\sessions.py", line 701, in send
    r = adapter.send(request, **kwargs)
  File "D:\Anaconda\envs\DL\lib\site-packages\requests\adapters.py", line 547, in send
    raise ConnectionError(err, request=request)
requests.exceptions.ConnectionError: ('Connection aborted.', ConnectionResetError(10054, '远程主机强迫关闭了一个现有的连接。', None, 10054, None))

During handling of the above exception, another exception occurred:

Traceback (most recent call last):
  File "D:\Anaconda\envs\DL\lib\site-packages\wandb\sdk\lib\retry.py", line 131, in __call__
    result = self._call_fn(*args, **kwargs)
  File "D:\Anaconda\envs\DL\lib\site-packages\wandb\sdk\internal\internal_api.py", line 2581, in upload_file
    raise _e.with_traceback(sys.exc_info()[2])
  File "D:\Anaconda\envs\DL\lib\site-packages\wandb\sdk\internal\internal_api.py", line 2550, in upload_file
    response = self._upload_file_session.put(
  File "D:\Anaconda\envs\DL\lib\site-packages\requests\sessions.py", line 647, in put
    return self.request("PUT", url, data=data, **kwargs)
  File "D:\Anaconda\envs\DL\lib\site-packages\requests\sessions.py", line 587, in request
    resp = self.send(prep, **send_kwargs)
  File "D:\Anaconda\envs\DL\lib\site-packages\requests\sessions.py", line 701, in send
    r = adapter.send(request, **kwargs)
  File "D:\Anaconda\envs\DL\lib\site-packages\requests\adapters.py", line 547, in send
    raise ConnectionError(err, request=request)
wandb.sdk.lib.retry.TransientError: None
2024-05-17 11:39:58,744 DEBUG   HandlerThread:32304 [handler.py:handle_request():146] handle_request: status_report
2024-05-17 11:39:58,965 INFO    Thread-16 :32304 [dir_watcher.py:_on_file_modified():288] file/dir modified: D:\Pycharm\ultralytics-main\wandb\run-20240517_113942-hdn8hdwc\files\output.log
2024-05-17 11:40:00,979 INFO    Thread-16 :32304 [dir_watcher.py:_on_file_modified():288] file/dir modified: D:\Pycharm\ultralytics-main\wandb\run-20240517_113942-hdn8hdwc\files\output.log
2024-05-17 11:40:02,816 ERROR   wandb-upload_0:32304 [internal_api.py:upload_file():2557] upload_file exception https://storage.googleapis.com/wandb-production.appspot.com/666233/runs/hdn8hdwc/wandb-metadata.json?Expires=1716003592&GoogleAccessId=gorilla-files-url-signer-man%40wandb-production.iam.gserviceaccount.com&Signature=LpwFdENp4zmX4uWoq0uykAxdGsEbHuep5mjx%2FN71x3YiFjNukKLH9Z%2FdnEU2SCYS8AGhOO5%2FbgJcxYA1yQSN%2FF6PF%2FdwZP7cp4rcbVccXIp7C8LH%2FkbqMCu%2FNLnkrObv1EJEwHQH%2BBsorOmIU0A9Z0zP7PFnn24W9JOHuwGF9OvjflLJuOylqPHWNtk1DqOPJecyxenhgFvVQBH6C4wwV2se6MS%2BGssvYyHr7d0Kom2oLyNHWsDXftPD0qhsII9xa9zHyaDwp44ZsepcnzbesAzliuV5tPgFnlkI7wsM%2BND2ErGKHHDQOs9DCyFJoXy52C7Gk9CmD8ZzmR0nlJRn6w%3D%3D: ('Connection aborted.', ConnectionResetError(10054, '远程主机强迫关闭了一个现有的连接。', None, 10054, None))
2024-05-17 11:40:02,816 ERROR   wandb-upload_0:32304 [internal_api.py:upload_file():2559] upload_file request headers: {'User-Agent': 'python-requests/2.28.2', 'Accept-Encoding': 'gzip, deflate', 'Accept': '*/*', 'Connection': 'keep-alive', 'Content-Length': '1195'}
2024-05-17 11:40:02,816 ERROR   wandb-upload_0:32304 [internal_api.py:upload_file():2561] upload_file response body: 
2024-05-17 11:40:03,896 DEBUG   HandlerThread:32304 [handler.py:handle_request():146] handle_request: status_report
